Workbook

Sheet Ens. Plomo
A1: MINERA MEXICANA LA CIENEGA, S.A. DE C.V.
A5: COMPARACION DE ENSAYES
A7: Lotes cerrados febrero 2026.
A9: CONCENTRADO DE PLOMO
C10: Au | D10: Ag | E10: Pb | F10: Zn | G10: Cd | H10: As | I10: Sb | J10: Hg.
C11: g/Ton | D11: Kg/Ton | E11: % | F11: % | G11: % | H11: % | I11: % | J11: %
A12: LOTE MMP | B12: LOTE MINA
A13: =[1]Plomo!$A9 -> P20260350 | B13: =[1]Plomo!$B9 -> 06 | C13: =[1]Plomo!C9 -> 113.55 | D13: =[1]Plomo!F9 -> 15.248 | E13: =[1]Plomo!I9 -> 20.75 | F13: =[1]Plomo!L9 -> 22.2 | G13: =[1]Plomo!O9 -> 0.239 | H13: =[1]Plomo!R9 -> 0.05 | I13: =[1]Plomo!U9 -> 0.07 | J13: =[1]Plomo!X9 -> 0.0069
A14: =[1]Plomo!$A10 -> P20260351 | B14: =[1]Plomo!$B10 -> 07 | C14: =[1]Plomo!C10 -> 113.9 | D14: =[1]Plomo!F10 -> 14.532 | E14: =[1]Plomo!I10 -> 21.66 | F14: =[1]Plomo!L10 -> 22.45 | G14: =[1]Plomo!O10 -> 0.24 | H14: =[1]Plomo!R10 -> 0.06 | I14: =[1]Plomo!U10 -> 0.07 | J14: =[1]Plomo!X10 -> 0.007
A15: =[1]Plomo!$A11 -> P20260405 | B15: =[1]Plomo!$B11 -> 08 | C15: =[1]Plomo!C11 -> 185.26 | D15: =[1]Plomo!F11 -> 15.101 | E15: =[1]Plomo!I11 -> 24.47 | F15: =[1]Plomo!L11 -> 20.99 | G15: =[1]Plomo!O11 -> 0.244 | H15: =[1]Plomo!R11 -> 0.049 | I15: =[1]Plomo!U11 -> 0.05 | J15: =[1]Plomo!X11 -> 0.0069
A16: =[1]Plomo!$A12 -> P20260406 | B16: =[1]Plomo!$B12 -> 09 | C16: =[1]Plomo!C12 -> 176.07 | D16: =[1]Plomo!F12 -> 14.903 | E16: =[1]Plomo!I12 -> 23.94 | F16: =[1]Plomo!L12 -> 21.8 | G16: =[1]Plomo!O12 -> 0.255 | H16: =[1]Plomo!R12 -> 0.045 | I16: =[1]Plomo!U12 -> 0.06 | J16: =[1]Plomo!X12 -> 0.007
D20: Ing. Laura D. Medina Carranza
D21: Gerencia Administrativa OFSA

Sheet Pb
A1: ='Ens. Zinc'!A1:G1 -> MINERA MEXICANA LA CIENEGA, S.A. DE C.V.
A2: CUADRO PARA DETERMINAR LOS ANALISIS EN CONJUNTO
A3: ='Ens. Plomo'!$A$7:$G$7 -> Lotes cerrados febrero 2026.
A4: CONCENTRADO DE PLOMO
A6: LOTE | C6: ENSAYES DE ORO | I6: ENSAYES DE PLATA KGS/TON | O6: ENSAYES DE PLOMO | U6: ENSAYES DE ZINC | AA6: ENSAYES DE CADMIO | AG6: ENSAYES DE ARSENICO (.3) | AM6: ENSAYES DE ANTIMONIO | AS6: ENSAYES DE MERCURIO PPM (LIBRE 50 PPM) | AY6: P = Promedio | BA6: Propuesta de Promedio
C7: Met-Mex | D7: Ciénega | E7: Dif | F7: L.P. | G7: INT. | H7: Final | I7: Met-Mex | J7: Ciénega | K7: Dif | L7: L.P. | M7: INT. | N7: Final | O7: Met-Mex | P7: Ciénega | Q7: Dif | R7: L.P. | S7: INT. | T7: Final | U7: Met-Mex | V7: Ciénega | W7: Dif | X7: L.P. | Y7: INT. | Z7: Final | AA7: Met-Mex | AB7: Ciénega | AC7: Dif | AD7: L.P. | AE7: INT. | AF7: Final | AG7: Met-Mex | AH7: Ciénega | AI7: Dif | AJ7: L.P. | AK7: INT. | AL7: Final | AM7: Met-Mex | AN7: Ciénega | AO7: Dif | AP7: L.P. | AQ7: INT. | AR7: Final | AS7: Met-Mex | AT7: Ciénega | AU7: Dif | AV7: L.P. | AW7: INT. | AX7: Final | AY7: T = Tercería | BA7: L.P.s diferentes.
B8: ='Ens. Plomo'!B13 -> 06 | C8: 112.64 | D8: ='Ens. Plomo'!C13 -> 113.55 | E8: =ROUND(ABS(C8-D8),2) -> 0.91 | F8: =(IF(D8<1,0,IF(AND(D8>=1,D8<=10),0.3,IF(AND(D8>10,D8<=25),0.5,IF(AND(D8>25,D8<=60),1,IF(AND(D8>60,D8<=75),1.25,IF(D8>75,2))))))) -> 2 | G8: =IF(E8<=F8,"P","T") -> P | H8: =IF(ISBLANK(C8)," ",IF(G8="P",AVERAGE(C8,D8),0)) -> 113.095 | I8: 14.828 | J8: ='Ens. Plomo'!D13 -> 15.248 | K8: =ROUND(ABS(I8-J8),3) -> 0.42 | L8: =(IF(J8<1,0, IF(AND(J8>=1,J8<=5),0.03, IF(AND(J8>5,J8<=15),0.04,IF(AND(J8>15,J8<=20),0.1,IF(J8>20,0.15)))))) -> 0.1 | M8: =IF(K8<=L8,"P","T") -> T | N8: =IF(ISBLANK(I8)," ",IF(K8<=L8,AVERAGE(I8:J8),0)) -> 0 | O8: 20.55 | P8: ='Ens. Plomo'!E13 -> 20.75 | Q8: =ROUND(ABS(O8-P8),2) -> 0.2 | R8: =(IF(P8<10,0,IF(AND(P8>10,P8<=20),0.3,IF(AND(P8>20,P8<=40),0.5)))) -> 0.5 | S8: =IF(Q8<=R8,"P","T") -> P | T8: =IF(ISBLANK(O8)," ",IF(Q8<=R8,AVERAGE(O8:P8),0)) -> 20.65 | U8: 24.2 | V8: ='Ens. Plomo'!F13 -> 22.2 | W8: =ROUND(ABS(U8-V8),2) -> 2 | X8: =(IF(V8<5,0,IF(AND(V8>=5,V8<=10),0.3,IF(AND(V8>10),0.4)))) -> 0.4 | Y8: =IF(W8<=X8,"P","T") -> T | Z8: =IF(ISBLANK(U8)," ",IF(Y8="P",AVERAGE(U8,V8),0)) -> 0 | AA8: 0.29 | AB8: ='Ens. Plomo'!G13 -> 0.239 | AC8: =ROUND(ABS(AA8-AB8),3) -> 0.051 | AD8: =IF(AB8<=1,0.1,0) -> 0.1 | AE8: =IF(AC8<=AD8,"P","T") -> P | AF8: =IF(ISBLANK(AA8)," ",IF(AE8="P",AVERAGE(AA8,AB8),0)) -> 0.2645 | AG8: 0.03 | AH8: ='Ens. Plomo'!H13 -> 0.05 | AI8: =ROUND(ABS(AG8-AH8),3) -> 0.02 | AJ8: =IF(AH8<=1,0.2,0) -> 0.2 | AK8: =IF(AI8<=AJ8,"P","T") -> P | AL8: =IF(ISBLANK(AG8)," ",IF(AK8="P",AVERAGE(AG8,AH8),0)) -> 0.04 | AM8: 0.06 | AN8: ='Ens. Plomo'!I13 -> 0.07 | AO8: =ROUND(ABS(AM8-AN8),2) -> 0.01 | AP8: =IF(AN8<=1,0.2,0) -> 0.2 | AQ8: =IF(AO8<=AP8,"P","T") -> P | AR8: =IF(ISBLANK(AM8)," ",IF(AQ8="P",AVERAGE(AM8,AN8),0)) -> 0.065 | AS8: 0.0332 | AT8: ='Ens. Plomo'!J13 -> 0.0069 | AU8: =AS8-AT8 -> 0.0263 | AV8: =IF(AT8<=0.01,0.0015,IF(AT8>0.01,0.002)) -> 0.0015 | AW8: =IF(AU8<=AV8,"P","T") -> T | AX8: =IF(ISBLANK(AS8)," ",IF(AW8="P",AVERAGE(AS8,AT8),0)) -> 0 | AY8: Conjunto Negociado | BA8: L.P.s diferentes.
B9: ='Ens. Plomo'!B14 -> 07 | C9: 109.68 | D9: ='Ens. Plomo'!C14 -> 113.9 | E9: =ROUND(ABS(C9-D9),2) -> 4.22 | F9: =(IF(D9<1,0,IF(AND(D9>=1,D9<=10),0.3,IF(AND(D9>10,D9<=25),0.5,IF(AND(D9>25,D9<=60),1,IF(AND(D9>60,D9<=75),1.25,IF(D9>75,2))))))) -> 2 | G9: =IF(E9<=F9,"P","T") -> T | H9: =IF(ISBLANK(C9)," ",IF(G9="P",AVERAGE(C9,D9),0)) -> 0 | I9: 14.161 | J9: ='Ens. Plomo'!D14 -> 14.532 | K9: =ROUND(ABS(I9-J9),3) -> 0.371 | L9: =(IF(J9<1,0, IF(AND(J9>=1,J9<=5),0.03, IF(AND(J9>5,J9<=15),0.04,IF(AND(J9>15,J9<=20),0.1,IF(J83>20,0.15)))))) -> 0.04 | M9: =IF(K9<=L9,"P","T") -> T | N9: =IF(ISBLANK(I9)," ",IF(K9<=L9,AVERAGE(I9:J9),0)) -> 0 | O9: 20.7 | P9: ='Ens. Plomo'!E14 -> 21.66 | Q9: =ROUND(ABS(O9-P9),2) -> 0.96 | R9: =(IF(P9<10,0,IF(AND(P9>10,P9<=20),0.3,IF(AND(P9>20,P9<=40),0.5)))) -> 0.5 | S9: =IF(Q9<=R9,"P","T") -> T | T9: =IF(ISBLANK(O9)," ",IF(Q9<=R9,AVERAGE(O9:P9),0)) -> 0 | U9: 24.38 | V9: ='Ens. Plomo'!F14 -> 22.45 | W9: =ROUND(ABS(U9-V9),2) -> 1.93 | X9: =(IF(V9<5,0,IF(AND(V9>=5,V9<=10),0.3,IF(AND(V9>10),0.4)))) -> 0.4 | Y9: =IF(W9<=X9,"P","T") -> T | Z9: =IF(ISBLANK(U9)," ",IF(Y9="P",AVERAGE(U9,V9),0)) -> 0 | AA9: 0.28 | AB9: ='Ens. Plomo'!G14 -> 0.24 | AC9: =ROUND(ABS(AA9-AB9),3) -> 0.04 | AD9: =IF(AB9<=1,0.1,0) -> 0.1 | AE9: =IF(AC9<=AD9,"P","T") -> P | AF9: =IF(ISBLANK(AA9)," ",IF(AE9="P",AVERAGE(AA9,AB9),0)) -> 0.26 | AG9: 0.03 | AH9: ='Ens. Plomo'!H14 -> 0.06 | AI9: =ROUND(ABS(AG9-AH9),3) -> 0.03 | AJ9: =IF(AH9<=1,0.2,0) -> 0.2 | AK9: =IF(AI9<=AJ9,"P","T") -> P | AL9: =IF(ISBLANK(AG9)," ",IF(AK9="P",AVERAGE(AG9,AH9),0)) -> 0.045 | AM9: 0.07 | AN9: ='Ens. Plomo'!I14 -> 0.07 | AO9: =ROUND(ABS(AM9-AN9),2) -> 0 | AP9: =IF(AN9<=1,0.2,0) -> 0.2 | AQ9: =IF(AO9<=AP9,"P","T") -> P | AR9: =IF(ISBLANK(AM9)," ",IF(AQ9="P",AVERAGE(AM9,AN9),0)) -> 0.07 | AS9: 0.0309 | AT9: ='Ens. Plomo'!J14 -> 0.007 | AU9: =AS9-AT9 -> 0.0239 | AV9: =IF(AT9<=0.01,0.0015,IF(AT9>0.01,0.002)) -> 0.0015 | AW9: =IF(AU9<=AV9,"P","T") -> T | AX9: =IF(ISBLANK(AS9)," ",IF(AW9="P",AVERAGE(AS9,AT9),0)) -> 0 | BA9: L.P.s diferentes.
B10: ='Ens. Plomo'!B15 -> 08 | C10: 180.88 | D10: ='Ens. Plomo'!C15 -> 185.26 | E10: =ROUND(ABS(C10-D10),2) -> 4.38 | F10: =(IF(D10<1,0,IF(AND(D10>=1,D10<=10),0.3,IF(AND(D10>10,D10<=25),0.5,IF(AND(D10>25,D10<=60),1,IF(AND(D10>60,D10<=75),1.25,IF(D10>75,2))))))) -> 2 | G10: =IF(E10<=F10,"P","T") -> T | H10: =IF(ISBLANK(C10)," ",IF(G10="P",AVERAGE(C10,D10),0)) -> 0 | I10: 14.683 | J10: ='Ens. Plomo'!D15 -> 15.101 | K10: =ROUND(ABS(I10-J10),3) -> 0.418 | L10: =(IF(J10<1,0, IF(AND(J10>=1,J10<=5),0.03, IF(AND(J10>5,J10<=15),0.04,IF(AND(J10>15,J10<=20),0.1,IF(J84>20,0.15)))))) -> 0.1 | M10: =IF(K10<=L10,"P","T") -> T | N10: =IF(ISBLANK(I10)," ",IF(K10<=L10,AVERAGE(I10:J10),0)) -> 0 | O10: 23.56 | P10: ='Ens. Plomo'!E15 -> 24.47 | Q10: =ROUND(ABS(O10-P10),2) -> 0.91 | R10: =(IF(P10<10,0,IF(AND(P10>10,P10<=20),0.3,IF(AND(P10>20,P10<=40),0.5)))) -> 0.5 | S10: =IF(Q10<=R10,"P","T") -> T | T10: =IF(ISBLANK(O10)," ",IF(Q10<=R10,AVERAGE(O10:P10),0)) -> 0 | U10: 22.71 | V10: ='Ens. Plomo'!F15 -> 20.99 | W10: =ROUND(ABS(U10-V10),2) -> 1.72 | X10: =(IF(V10<5,0,IF(AND(V10>=5,V10<=10),0.3,IF(AND(V10>10),0.4)))) -> 0.4 | Y10: =IF(W10<=X10,"P","T") -> T | Z10: =IF(ISBLANK(U10)," ",IF(Y10="P",AVERAGE(U10,V10),0)) -> 0 | AA10: 0.28 | AB10: ='Ens. Plomo'!G15 -> 0.244 | AC10: =ROUND(ABS(AA10-AB10),3) -> 0.036 | AD10: =IF(AB10<=1,0.1,0) -> 0.1 | AE10: =IF(AC10<=AD10,"P","T") -> P | AF10: =IF(ISBLANK(AA10)," ",IF(AE10="P",AVERAGE(AA10,AB10),0)) -> 0.262 | AG10: 0.03 | AH10: ='Ens. Plomo'!H15 -> 0.049 | AI10: =ROUND(ABS(AG10-AH10),3) -> 0.019 | AJ10: =IF(AH10<=1,0.2,0) -> 0.2 | AK10: =IF(AI10<=AJ10,"P","T") -> P | AL10: =IF(ISBLANK(AG10)," ",IF(AK10="P",AVERAGE(AG10,AH10),0)) -> 0.0395 | AM10: 0.06 | AN10: ='Ens. Plomo'!I15 -> 0.05 | AO10: =ROUND(ABS(AM10-AN10),3) -> 0.01 | AP10: =IF(AN10<=1,0.2,0) -> 0.2 | AQ10: =IF(AO10<=AP10,"P","T") -> P | AR10: =IF(ISBLANK(AM10)," ",IF(AQ10="P",AVERAGE(AM10,AN10),0)) -> 0.055 | AS10: 0.0303 | AT10: ='Ens. Plomo'!J15 -> 0.0069 | AU10: =AS10-AT10 -> 0.0234 | AV10: =IF(AT10<=0.01,0.0015,IF(AT10>0.01,0.002)) -> 0.0015 | AW10: =IF(AU10<=AV10,"P","T") -> T | AX10: =IF(ISBLANK(AS10)," ",IF(AW10="P",AVERAGE(AS10,AT10),0)) -> 0 | BA10: L.P.s diferentes.
B11: ='Ens. Plomo'!B16 -> 09 | C11: 171.83 | D11: ='Ens. Plomo'!C16 -> 176.07 | E11: =ROUND(ABS(C11-D11),2) -> 4.24 | F11: =(IF(D11<1,0,IF(AND(D11>=1,D11<=10),0.3,IF(AND(D11>10,D11<=25),0.5,IF(AND(D11>25,D11<=60),1,IF(AND(D11>60,D11<=75),1.25,IF(D11>75,2))))))) -> 2 | G11: =IF(E11<=F11,"P","T") -> T | H11: =IF(ISBLANK(C11)," ",IF(G11="P",AVERAGE(C11,D11),0)) -> 0 | I11: 14.602 | J11: ='Ens. Plomo'!D16 -> 14.903 | K11: =ROUND(ABS(I11-J11),3) -> 0.301 | L11: =(IF(J11<1,0, IF(AND(J11>=1,J11<=5),0.03, IF(AND(J11>5,J11<=15),0.04,IF(AND(J11>15,J11<=20),0.1,IF(J85>20,0.15)))))) -> 0.04 | M11: =IF(K11<=L11,"P","T") -> T | N11: =IF(ISBLANK(I11)," ",IF(K11<=L11,AVERAGE(I11:J11),0)) -> 0 | O11: 23.57 | P11: ='Ens. Plomo'!E16 -> 23.94 | Q11: =ROUND(ABS(O11-P11),2) -> 0.37 | R11: =(IF(P11<10,0,IF(AND(P11>10,P11<=20),0.3,IF(AND(P11>20,P11<=40),0.5)))) -> 0.5 | S11: =IF(Q11<=R11,"P","T") -> P | T11: =IF(ISBLANK(O11)," ",IF(Q11<=R11,AVERAGE(O11:P11),0)) -> 23.755 | U11: 23.12 | V11: ='Ens. Plomo'!F16 -> 21.8 | W11: =ROUND(ABS(U11-V11),2) -> 1.32 | X11: =(IF(V11<5,0,IF(AND(V11>=5,V11<=10),0.3,IF(AND(V11>10),0.4)))) -> 0.4 | Y11: =IF(W11<=X11,"P","T") -> T | Z11: =IF(ISBLANK(U11)," ",IF(Y11="P",AVERAGE(U11,V11),0)) -> 0 | AA11: 0.29 | AB11: ='Ens. Plomo'!G16 -> 0.255 | AC11: =ROUND(ABS(AA11-AB11),3) -> 0.035 | AD11: =IF(AB11<=1,0.1,0) -> 0.1 | AE11: =IF(AC11<=AD11,"P","T") -> P | AF11: =IF(ISBLANK(AA11)," ",IF(AE11="P",AVERAGE(AA11,AB11),0)) -> 0.2725 | AG11: 0.03 | AH11: ='Ens. Plomo'!H16 -> 0.045 | AI11: =ROUND(ABS(AG11-AH11),3) -> 0.015 | AJ11: =IF(AH11<=1,0.2,0) -> 0.2 | AK11: =IF(AI11<=AJ11,"P","T") -> P | AL11: =IF(ISBLANK(AG11)," ",IF(AK11="P",AVERAGE(AG11,AH11),0)) -> 0.0375 | AM11: 0.06 | AN11: ='Ens. Plomo'!I16 -> 0.06 | AO11: =ROUND(ABS(AM11-AN11),3) -> 0 | AP11: =IF(AN11<=1,0.2,0) -> 0.2 | AQ11: =IF(AO11<=AP11,"P","T") -> P | AR11: =IF(ISBLANK(AM11)," ",IF(AQ11="P",AVERAGE(AM11,AN11),0)) -> 0.06 | AS11: 0.0285 | AT11: ='Ens. Plomo'!J16 -> 0.007 | AU11: =AS11-AT11 -> 0.0215 | AV11: =IF(AT11<=0.01,0.0015,IF(AT11>0.01,0.002)) -> 0.0015 | AW11: =IF(AU11<=AV11,"P","T") -> T | AX11: =IF(ISBLANK(AS11)," ",IF(AW11="P",AVERAGE(AS11,AT11),0)) -> 0 | BA11: L.P.s diferentes.
M12: =IF(K12<=L12,"P","T") -> P | AW12: =IF(AU12<=AV12,"P","T") -> P

Sheet Terc. Plomo
A1: MINERA MEXICANA LA CIÉNEGA, S.A. DE C.V.
A3: CUADRO PARA DETERMINAR DIFERENCIAS EN ENSAYES COMPARADOS
A6: =+Pb!A3 -> Lotes cerrados febrero 2026.
T7: PLOMO
A8: No. | B8: Ensayes de ORO g/ton | G8: Dif. Vs Tercero | I8: Paga | J8: Ensayes de PLATA Kg/ton | O8: Dif. Vs Tercero | Q8: Paga | R8: Ensayes de PLOMO % | W8: Dif. Vs Tercero | Y8: Paga | Z8: Ensayes de ZINC % | AE8: Dif. Vs Tercero | AG8: Paga | AH8: Ensayes de CADMIO % | AM8: Dif. Vs Tercero | AO8: Paga | AP8: Ensayes de MERCURIO % | AU8: Dif. Vs Tercero | AW8: Paga | AX8: Ensayes de ARSENICO % | BC8: Dif. Vs Tercero | BE8: Paga | BF8: Ensayes de ANTIMONIO % | BK8: Dif. Vs Tercero | BM8: Paga
A9: Lote | B9: MMP | C9: CIEN | D9: Tercero | E9: INT. | F9: Pago | G9: MMP | H9: CIEN | I9: Terceria | J9: MMP | K9: CIEN | L9: Tercero | N9: Pago | O9: MMP | P9: CIEN | Q9: Terceria | R9: MMP | S9: CIEN | T9: Tercero | V9: Pago | W9: MMP | X9: CIEN | Y9: Terceria | Z9: MMP | AA9: CIEN | AB9: Tercero | AD9: Pago | AE9: MMP | AF9: CIEN | AG9: Terceria | AH9: MMP | AI9: CIEN | AJ9: Tercero | AL9: Pago | AM9: MMP | AN9: 0 | AO9: Terceria | AP9: MMP | AQ9: CIEN | AR9: Tercero | AT9: Pago | AU9: MMP | AV9: CIEN | AW9: Terceria | AX9: MMP | AY9: CIEN | AZ9: Tercero | BB9: Pago | BC9: MMP | BD9: CIEN | BE9: Terceria | BF9: MMP | BG9: CIEN | BH9: Tercero | BJ9: Pago | BK9: MMP | BL9: CIEN | BM9: Terceria
A10: =Pb!B8 -> 06 | B10: =+Pb!C8 -> 112.64 | C10: =Pb!D8 -> 113.55 | E10: =+Pb!G8 -> P | F10: =IF(D10=0,AVERAGE(B10,C10),IF(OR(AND(B10<C10,B10>D10),AND(B10>C10,B10<D10)),B10,IF(OR(AND(C10<B10,C10>D10),AND(C10>B10,C10<D10)),C10,D10))) -> 113.095 | G10: =IF(D10=0,0,IF(D10>B10,(D10-B10),(B10-D10))) -> 0 | H10: =IF(D10=0,0,IF(C10>D10,(C10-D10),(D10-C10))) -> 0 | I10: =IF(D10=0,"",IF(H10=G10,"50%",IF(H10>G10,"CIEN","MMP"))) | J10: =+Pb!I8 -> 14.828 | K10: =Pb!J8 -> 15.248 | L10: 15.233 | M10: =+Pb!M8 -> T | N10: =IF(L10=0,AVERAGE(J10,K10),IF(OR(AND(J10<K10,J10>L10),AND(J10>K10,J10<L10)),J10,IF(OR(AND(K10<J10,K10>L10),AND(K10>J10,K10<L10)),K10,L10))) -> 15.233 | O10: =IF(L10=0,0,IF(L10>J10,(L10-J10),(J10-L10))) -> 0.405 | P10: =IF(L10=0,0,IF(K10>L10,(K10-L10),(L10-K10))) -> 0.015 | Q10: =IF(L10=0,"",IF(P10=O10,"50%",IF(P10>O10,"CIEN","MMP"))) -> MMP | R10: =+Pb!O8 -> 20.55 | S10: =Pb!P8 -> 20.75 | U10: =+Pb!S8 -> P | V10: =IF(T10=0,AVERAGE(R10,S10),IF(OR(AND(R10<S10,R10>T10),AND(R10>S10,R10<T10)),R10,IF(OR(AND(S10<R10,S10>T10),AND(S10>R10,S10<T10)),S10,T10))) -> 20.65 | W10: =IF(T10=0,0,IF(T10>R10,(T10-R10),(R10-T10))) -> 0 | X10: =IF(T10=0,0,IF(S10>T10,(S10-T10),(T10-S10))) -> 0 | Y10: =IF(T10=0,"",IF(X10=W10,"50%",IF(X10>W10,"CIEN","MMP"))) | Z10: =+Pb!U8 -> 24.2 | AA10: =Pb!V8 -> 22.2 | AB10: 20.935 | AC10: =+Pb!Y8 -> T | AD10: =IF(AB10=0,AVERAGE(Z10,AA10),IF(OR(AND(Z10<AA10,Z10>AB10),AND(Z10>AA10,Z10<AB10)),Z10,IF(OR(AND(AA10<Z10,AA10>AB10),AND(AA10>Z10,AA10<AB10)),AA10,AB10))) -> 22.2 | AE10: =IF(AB10>Z10,(AB10-Z10),(Z10-AB10)) -> 3.265 | AF10: =IF(AA10>AB10,(AA10-AB10),(AB10-AA10)) -> 1.265 | AG10: =IF(AB10=0,"",IF(AF10=AE10,"50%",IF(AF10>AE10,"CIEN","MMP"))) -> MMP | AH10: =+Pb!AA8 -> 0.29 | AI10: =Pb!AB8 -> 0.239 | AK10: =+Pb!AE8 -> P | AL10: =IF(AJ10=0,AVERAGE(AH10,AI10),IF(OR(AND(AH10<AI10,AH10>AJ10),AND(AH10>AI10,AH10<AJ10)),AH10,IF(OR(AND(AI10<AH10,AI10>AJ10),AND(AI10>AH10,AI10<AJ10)),AI10,AJ10))) -> 0.2645 | AM10: =IF(AJ10>AH10,(AJ10-AH10),(AH10-AJ10)) -> 0.29 | AN10: =IF(AI10>AJ10,(AI10-AJ10),(AJ10-AI10)) -> 0.239 | AO10: =IF(AJ10=0,"",IF(AN10=AM10,"50%",IF(AN10>AM10,"CIEN","MMP"))) | AP10: =+Pb!AS8 -> 0.0332 | AQ10: =Pb!AT8 -> 0.0069 | AR10: 0.0532 | AS10: =+Pb!AW8 -> T | AT10: =IF(AR10=0,AVERAGE(AP10,AQ10),IF(OR(AND(AP10<AQ10,AP10>AR10),AND(AP10>AQ10,AP10<AR10)),AP10,IF(OR(AND(AQ10<AP10,AQ10>AR10),AND(AQ10>AP10,AQ10<AR10)),AQ10,AR10))) -> 0.0332 | AU10: =IF(AR10>AP10,(AR10-AP10),(AP10-AR10)) -> 0.02 | AV10: =IF(AQ10>AR10,(AQ10-AR10),(AR10-AQ10)) -> 0.0463 | AW10: =IF(AR10=0,"",IF(AV10=AU10,"50%",IF(AV10>AU10,"CIEN","MMP"))) -> CIEN | AX10: =+Pb!AG8 -> 0.03 | AY10: =Pb!AH8 -> 0.05 | BA10: =+Pb!AK8 -> P | BB10: =IF(AZ10=0,AVERAGE(AX10,AY10),IF(OR(AND(AX10<AY10,AX10>AZ10),AND(AX10>AY10,AX10<AZ10)),AX10,IF(OR(AND(AY10<AX10,AY10>AZ10),AND(AY10>AX10,AY10<AZ10)),AY10,AZ10))) -> 0.04 | BC10: =IF(AZ10>AX10,(AZ10-AX10),(AX10-AZ10)) -> 0.03 | BD10: =IF(AY10>AZ10,(AY10-AZ10),(AZ10-AY10)) -> 0.05 | BE10: =IF(AZ10=0,"",IF(BD10=BC10,"50%",IF(BD10>BC10,"CIEN","MMP"))) | BF10: =+Pb!AM8 -> 0.06 | BG10: =Pb!AN8 -> 0.07 | BI10: =+Pb!AQ8 -> P | BJ10: =IF(BH10=0,AVERAGE(BF10,BG10),IF(OR(AND(BF10<BG10,BF10>BH10),AND(BF10>BG10,BF10<BH10)),BF10,IF(OR(AND(BG10<BF10,BG10>BH10),AND(BG10>BF10,BG10<BH10)),BG10,BH10))) -> 0.065 | BK10: =IF(BH10>BF10,(BH10-BF10),(BF10-BH10)) -> 0.06 | BL10: =IF(BG10>BH10,(BG10-BH10),(BH10-BG10)) -> 0.07 | BM10: =IF(BH10=0,"",IF(BL10=BK10,"50%",IF(BL10>BK10,"CIEN","MMP"))) | BP10: ALEX STEWART
A11: =Pb!B9 -> 07 | B11: =+Pb!C9 -> 109.68 | C11: =Pb!D9 -> 113.9 | D11: 114.085 | E11: =+Pb!G9 -> T | F11: =IF(D11=0,AVERAGE(B11,C11),IF(OR(AND(B11<C11,B11>D11),AND(B11>C11,B11<D11)),B11,IF(OR(AND(C11<B11,C11>D11),AND(C11>B11,C11<D11)),C11,D11))) -> 113.9 | G11: =IF(D11=0,0,IF(D11>B11,(D11-B11),(B11-D11))) -> 4.405 | H11: =IF(D11=0,0,IF(C11>D11,(C11-D11),(D11-C11))) -> 0.185 | I11: =IF(D11=0,"",IF(H11=G11,"50%",IF(H11>G11,"CIEN","MMP"))) -> MMP | J11: =+Pb!I9 -> 14.161 | K11: =Pb!J9 -> 14.532 | L11: 14.704 | M11: =+Pb!M9 -> T | N11: =IF(L11=0,AVERAGE(J11,K11),IF(OR(AND(J11<K11,J11>L11),AND(J11>K11,J11<L11)),J11,IF(OR(AND(K11<J11,K11>L11),AND(K11>J11,K11<L11)),K11,L11))) -> 14.532 | O11: =IF(L11=0,0,IF(L11>J11,(L11-J11),(J11-L11))) -> 0.543 | P11: =IF(L11=0,0,IF(K11>L11,(K11-L11),(L11-K11))) -> 0.172 | Q11: =IF(L11=0,"",IF(P11=O11,"50%",IF(P11>O11,"CIEN","MMP"))) -> MMP | R11: =+Pb!O9 -> 20.7 | S11: =Pb!P9 -> 21.66 | T11: 21.18 | U11: =+Pb!S9 -> T | V11: =IF(T11=0,AVERAGE(R11,S11),IF(OR(AND(R11<S11,R11>T11),AND(R11>S11,R11<T11)),R11,IF(OR(AND(S11<R11,S11>T11),AND(S11>R11,S11<T11)),S11,T11))) -> 21.18 | W11: =IF(T11=0,0,IF(T11>R11,(T11-R11),(R11-T11))) -> 0.48 | X11: =IF(T11=0,0,IF(S11>T11,(S11-T11),(T11-S11))) -> 0.48 | Y11: =IF(T11=0,"",IF(X11=W11,"50%",IF(X11>W11,"CIEN","MMP"))) -> 50% | Z11: =+Pb!U9 -> 24.38 | AA11: =Pb!V9 -> 22.45 | AB11: 20.585 | AC11: =+Pb!Y9 -> T | AD11: =IF(AB11=0,AVERAGE(Z11,AA11),IF(OR(AND(Z11<AA11,Z11>AB11),AND(Z11>AA11,Z11<AB11)),Z11,IF(OR(AND(AA11<Z11,AA11>AB11),AND(AA11>Z11,AA11<AB11)),AA11,AB11))) -> 22.45 | AE11: =IF(AB11>Z11,(AB11-Z11),(Z11-AB11)) -> 3.795 | AF11: =IF(AA11>AB11,(AA11-AB11),(AB11-AA11)) -> 1.865 | AG11: =IF(AB11=0,"",IF(AF11=AE11,"50%",IF(AF11>AE11,"CIEN","MMP"))) -> MMP | AH11: =+Pb!AA9 -> 0.28 | AI11: =Pb!AB9 -> 0.24 | AK11: =+Pb!AE9 -> P | AL11: =IF(AJ11=0,AVERAGE(AH11,AI11),IF(OR(AND(AH11<AI11,AH11>AJ11),AND(AH11>AI11,AH11<AJ11)),AH11,IF(OR(AND(AI11<AH11,AI11>AJ11),AND(AI11>AH11,AI11<AJ11)),AI11,AJ11))) -> 0.26 | AM11: =IF(AJ11>AH11,(AJ11-AH11),(AH11-AJ11)) -> 0.28 | AN11: =IF(AI11>AJ11,(AI11-AJ11),(AJ11-AI11)) -> 0.24 | AO11: =IF(AJ11=0,"",IF(AN11=AM11,"50%",IF(AN11>AM11,"CIEN","MMP"))) | AP11: =+Pb!AS9 -> 0.0309 | AQ11: =Pb!AT9 -> 0.007 | AR11: 0.0481 | AS11: =+Pb!AW9 -> T | AT11: =IF(AR11=0,AVERAGE(AP11,AQ11),IF(OR(AND(AP11<AQ11,AP11>AR11),AND(AP11>AQ11,AP11<AR11)),AP11,IF(OR(AND(AQ11<AP11,AQ11>AR11),AND(AQ11>AP11,AQ11<AR11)),AQ11,AR11))) -> 0.0309 | AU11: =IF(AR11>AP11,(AR11-AP11),(AP11-AR11)) -> 0.0172 | AV11: =IF(AQ11>AR11,(AQ11-AR11),(AR11-AQ11)) -> 0.0411 | AW11: =IF(AR11=0,"",IF(AV11=AU11,"50%",IF(AV11>AU11,"CIEN","MMP"))) -> CIEN | AX11: =+Pb!AG9 -> 0.03 | AY11: =Pb!AH9 -> 0.06 | BA11: =+Pb!AK9 -> P | BB11: =IF(AZ11=0,AVERAGE(AX11,AY11),IF(OR(AND(AX11<AY11,AX11>AZ11),AND(AX11>AY11,AX11<AZ11)),AX11,IF(OR(AND(AY11<AX11,AY11>AZ11),AND(AY11>AX11,AY11<AZ11)),AY11,AZ11))) -> 0.045 | BC11: =IF(AZ11>AX11,(AZ11-AX11),(AX11-AZ11)) -> 0.03 | BD11: =IF(AY11>AZ11,(AY11-AZ11),(AZ11-AY11)) -> 0.06 | BE11: =IF(AZ11=0,"",IF(BD11=BC11,"50%",IF(BD11>BC11,"CIEN","MMP"))) | BF11: =+Pb!AM9 -> 0.07 | BG11: =Pb!AN9 -> 0.07 | BI11: =+Pb!AQ9 -> P | BJ11: =IF(BH11=0,AVERAGE(BF11,BG11),IF(OR(AND(BF11<BG11,BF11>BH11),AND(BF11>BG11,BF11<BH11)),BF11,IF(OR(AND(BG11<BF11,BG11>BH11),AND(BG11>BF11,BG11<BH11)),BG11,BH11))) -> 0.07 | BK11: =IF(BH11>BF11,(BH11-BF11),(BF11-BH11)) -> 0.07 | BL11: =IF(BG11>BH11,(BG11-BH11),(BH11-BG11)) -> 0.07 | BM11: =IF(BH11=0,"",IF(BL11=BK11,"50%",IF(BL11>BK11,"CIEN","MMP"))) | BP11: LIM | BS11: NEGRITAS
A12: =Pb!B10 -> 08 | B12: =+Pb!C10 -> 180.88 | C12: =Pb!D10 -> 185.26 | D12: 180.81 | E12: =+Pb!G10 -> T | F12: =IF(D12=0,AVERAGE(B12,C12),IF(OR(AND(B12<C12,B12>D12),AND(B12>C12,B12<D12)),B12,IF(OR(AND(C12<B12,C12>D12),AND(C12>B12,C12<D12)),C12,D12))) -> 180.88 | G12: =IF(D12=0,0,IF(D12>B12,(D12-B12),(B12-D12))) -> 0.07 | H12: =IF(D12=0,0,IF(C12>D12,(C12-D12),(D12-C12))) -> 4.45 | I12: =IF(D12=0,"",IF(H12=G12,"50%",IF(H12>G12,"CIEN","MMP"))) -> CIEN | J12: =+Pb!I10 -> 14.683 | K12: =Pb!J10 -> 15.101 | L12: 14.838 | M12: =+Pb!M10 -> T | N12: =IF(L12=0,AVERAGE(J12,K12),IF(OR(AND(J12<K12,J12>L12),AND(J12>K12,J12<L12)),J12,IF(OR(AND(K12<J12,K12>L12),AND(K12>J12,K12<L12)),K12,L12))) -> 14.838 | O12: =IF(L12=0,0,IF(L12>J12,(L12-J12),(J12-L12))) -> 0.155 | P12: =IF(L12=0,0,IF(K12>L12,(K12-L12),(L12-K12))) -> 0.263 | Q12: =IF(L12=0,"",IF(P12=O12,"50%",IF(P12>O12,"CIEN","MMP"))) -> CIEN | R12: =+Pb!O10 -> 23.56 | S12: =Pb!P10 -> 24.47 | T12: 24.31 | U12: =+Pb!S10 -> T | V12: =IF(T12=0,AVERAGE(R12,S12),IF(OR(AND(R12<S12,R12>T12),AND(R12>S12,R12<T12)),R12,IF(OR(AND(S12<R12,S12>T12),AND(S12>R12,S12<T12)),S12,T12))) -> 24.31 | W12: =IF(T12=0,0,IF(T12>R12,(T12-R12),(R12-T12))) -> 0.75 | X12: =IF(T12=0,0,IF(S12>T12,(S12-T12),(T12-S12))) -> 0.16 | Y12: =IF(T12=0,"",IF(X12=W12,"50%",IF(X12>W12,"CIEN","MMP"))) -> MMP | Z12: =+Pb!U10 -> 22.71 | AA12: =Pb!V10 -> 20.99 | AB12: 21.33 | AC12: =+Pb!Y10 -> T | AD12: =IF(AB12=0,AVERAGE(Z12,AA12),IF(OR(AND(Z12<AA12,Z12>AB12),AND(Z12>AA12,Z12<AB12)),Z12,IF(OR(AND(AA12<Z12,AA12>AB12),AND(AA12>Z12,AA12<AB12)),AA12,AB12))) -> 21.33 | AE12: =IF(AB12>Z12,(AB12-Z12),(Z12-AB12)) -> 1.38 | AF12: =IF(AA12>AB12,(AA12-AB12),(AB12-AA12)) -> 0.34 | AG12: =IF(AB12=0,"",IF(AF12=AE12,"50%",IF(AF12>AE12,"CIEN","MMP"))) -> MMP | AH12: =+Pb!AA10 -> 0.28 | AI12: =Pb!AB10 -> 0.244 | AK12: =+Pb!AE10 -> P | AL12: =IF(AJ12=0,AVERAGE(AH12,AI12),IF(OR(AND(AH12<AI12,AH12>AJ12),AND(AH12>AI12,AH12<AJ12)),AH12,IF(OR(AND(AI12<AH12,AI12>AJ12),AND(AI12>AH12,AI12<AJ12)),AI12,AJ12))) -> 0.262 | AM12: =IF(AJ12>AH12,(AJ12-AH12),(AH12-AJ12)) -> 0.28 | AN12: =IF(AI12>AJ12,(AI12-AJ12),(AJ12-AI12)) -> 0.244 | AO12: =IF(AJ12=0,"",IF(AN12=AM12,"50%",IF(AN12>AM12,"CIEN","MMP"))) | AP12: =+Pb!AS10 -> 0.0303 | AQ12: =Pb!AT10 -> 0.0069 | AR12: 0.0211 | AS12: =+Pb!AW10 -> T | AT12: =IF(AR12=0,AVERAGE(AP12,AQ12),IF(OR(AND(AP12<AQ12,AP12>AR12),AND(AP12>AQ12,AP12<AR12)),AP12,IF(OR(AND(AQ12<AP12,AQ12>AR12),AND(AQ12>AP12,AQ12<AR12)),AQ12,AR12))) -> 0.0211 | AU12: =IF(AR12>AP12,(AR12-AP12),(AP12-AR12)) -> 0.0092 | AV12: =IF(AQ12>AR12,(AQ12-AR12),(AR12-AQ12)) -> 0.0142 | AW12: =IF(AR12=0,"",IF(AV12=AU12,"50%",IF(AV12>AU12,"CIEN","MMP"))) -> CIEN | AX12: =+Pb!AG10 -> 0.03 | AY12: =Pb!AH10 -> 0.049 | BA12: =+Pb!AK10 -> P | BB12: =IF(AZ12=0,AVERAGE(AX12,AY12),IF(OR(AND(AX12<AY12,AX12>AZ12),AND(AX12>AY12,AX12<AZ12)),AX12,IF(OR(AND(AY12<AX12,AY12>AZ12),AND(AY12>AX12,AY12<AZ12)),AY12,AZ12))) -> 0.0395 | BC12: =IF(AZ12>AX12,(AZ12-AX12),(AX12-AZ12)) -> 0.03 | BD12: =IF(AY12>AZ12,(AY12-AZ12),(AZ12-AY12)) -> 0.049 | BE12: =IF(AZ12=0,"",IF(BD12=BC12,"50%",IF(BD12>BC12,"CIEN","MMP"))) | BF12: =+Pb!AM10 -> 0.06 | BG12: =Pb!AN10 -> 0.05 | BI12: =+Pb!AQ10 -> P | BJ12: =IF(BH12=0,AVERAGE(BF12,BG12),IF(OR(AND(BF12<BG12,BF12>BH12),AND(BF12>BG12,BF12<BH12)),BF12,IF(OR(AND(BG12<BF12,BG12>BH12),AND(BG12>BF12,BG12<BH12)),BG12,BH12))) -> 0.055 | BK12: =IF(BH12>BF12,(BH12-BF12),(BF12-BH12)) -> 0.06 | BL12: =IF(BG12>BH12,(BG12-BH12),(BH12-BG12)) -> 0.05 | BM12: =IF(BH12=0,"",IF(BL12=BK12,"50%",IF(BL12>BK12,"CIEN","MMP"))) | BP12: COURTADE | BS12: KURSIVA
A13: =Pb!B11 -> 09 | B13: =+Pb!C11 -> 171.83 | C13: =Pb!D11 -> 176.07 | D13: 175.12 | E13: =+Pb!G11 -> T | F13: =IF(D13=0,AVERAGE(B13,C13),IF(OR(AND(B13<C13,B13>D13),AND(B13>C13,B13<D13)),B13,IF(OR(AND(C13<B13,C13>D13),AND(C13>B13,C13<D13)),C13,D13))) -> 175.12 | G13: =IF(D13=0,0,IF(D13>B13,(D13-B13),(B13-D13))) -> 3.29 | H13: =IF(D13=0,0,IF(C13>D13,(C13-D13),(D13-C13))) -> 0.95 | I13: =IF(D13=0,"",IF(H13=G13,"50%",IF(H13>G13,"CIEN","MMP"))) -> MMP | J13: =+Pb!I11 -> 14.602 | K13: =Pb!J11 -> 14.903 | L13: 14.751 | M13: =+Pb!M11 -> T | N13: =IF(L13=0,AVERAGE(J13,K13),IF(OR(AND(J13<K13,J13>L13),AND(J13>K13,J13<L13)),J13,IF(OR(AND(K13<J13,K13>L13),AND(K13>J13,K13<L13)),K13,L13))) -> 14.751 | O13: =IF(L13=0,0,IF(L13>J13,(L13-J13),(J13-L13))) -> 0.149 | P13: =IF(L13=0,0,IF(K13>L13,(K13-L13),(L13-K13))) -> 0.152 | Q13: =IF(L13=0,"",IF(P13=O13,"50%",IF(P13>O13,"CIEN","MMP"))) -> CIEN | R13: =+Pb!O11 -> 23.57 | S13: =Pb!P11 -> 23.94 | U13: =+Pb!S11 -> P | V13: =IF(T13=0,AVERAGE(R13,S13),IF(OR(AND(R13<S13,R13>T13),AND(R13>S13,R13<T13)),R13,IF(OR(AND(S13<R13,S13>T13),AND(S13>R13,S13<T13)),S13,T13))) -> 23.755 | W13: =IF(T13=0,0,IF(T13>R13,(T13-R13),(R13-T13))) -> 0 | X13: =IF(T13=0,0,IF(S13>T13,(S13-T13),(T13-S13))) -> 0 | Y13: =IF(T13=0,"",IF(X13=W13,"50%",IF(X13>W13,"CIEN","MMP"))) | Z13: =+Pb!U11 -> 23.12 | AA13: =Pb!V11 -> 21.8 | AB13: 21.74 | AC13: =+Pb!Y11 -> T | AD13: =IF(AB13=0,AVERAGE(Z13,AA13),IF(OR(AND(Z13<AA13,Z13>AB13),AND(Z13>AA13,Z13<AB13)),Z13,IF(OR(AND(AA13<Z13,AA13>AB13),AND(AA13>Z13,AA13<AB13)),AA13,AB13))) -> 21.8 | AE13: =IF(AB13>Z13,(AB13-Z13),(Z13-AB13)) -> 1.38 | AF13: =IF(AA13>AB13,(AA13-AB13),(AB13-AA13)) -> 0.06 | AG13: =IF(AB13=0,"",IF(AF13=AE13,"50%",IF(AF13>AE13,"CIEN","MMP"))) -> MMP | AH13: =+Pb!AA11 -> 0.29 | AI13: =Pb!AB11 -> 0.255 | AK13: =+Pb!AE11 -> P | AL13: =IF(AJ13=0,AVERAGE(AH13,AI13),IF(OR(AND(AH13<AI13,AH13>AJ13),AND(AH13>AI13,AH13<AJ13)),AH13,IF(OR(AND(AI13<AH13,AI13>AJ13),AND(AI13>AH13,AI13<AJ13)),AI13,AJ13))) -> 0.2725 | AM13: =IF(AJ13>AH13,(AJ13-AH13),(AH13-AJ13)) -> 0.29 | AN13: =IF(AI13>AJ13,(AI13-AJ13),(AJ13-AI13)) -> 0.255 | AO13: =IF(AJ13=0,"",IF(AN13=AM13,"50%",IF(AN13>AM13,"CIEN","MMP"))) | AP13: =+Pb!AS11 -> 0.0285 | AQ13: =Pb!AT11 -> 0.007 | AR13: 0.0195 | AS13: =+Pb!AW11 -> T | AT13: =IF(AR13=0,AVERAGE(AP13,AQ13),IF(OR(AND(AP13<AQ13,AP13>AR13),AND(AP13>AQ13,AP13<AR13)),AP13,IF(OR(AND(AQ13<AP13,AQ13>AR13),AND(AQ13>AP13,AQ13<AR13)),AQ13,AR13))) -> 0.0195 | AU13: =IF(AR13>AP13,(AR13-AP13),(AP13-AR13)) -> 0.009 | AV13: =IF(AQ13>AR13,(AQ13-AR13),(AR13-AQ13)) -> 0.0125 | AW13: =IF(AR13=0,"",IF(AV13=AU13,"50%",IF(AV13>AU13,"CIEN","MMP"))) -> CIEN | AX13: =+Pb!AG11 -> 0.03 | AY13: =Pb!AH11 -> 0.045 | BA13: =+Pb!AK11 -> P | BB13: =IF(AZ13=0,AVERAGE(AX13,AY13),IF(OR(AND(AX13<AY13,AX13>AZ13),AND(AX13>AY13,AX13<AZ13)),AX13,IF(OR(AND(AY13<AX13,AY13>AZ13),AND(AY13>AX13,AY13<AZ13)),AY13,AZ13))) -> 0.0375 | BC13: =IF(AZ13>AX13,(AZ13-AX13),(AX13-AZ13)) -> 0.03 | BD13: =IF(AY13>AZ13,(AY13-AZ13),(AZ13-AY13)) -> 0.045 | BE13: =IF(AZ13=0,"",IF(BD13=BC13,"50%",IF(BD13>BC13,"CIEN","MMP"))) | BF13: =+Pb!AM11 -> 0.06 | BG13: =Pb!AN11 -> 0.06 | BI13: =+Pb!AQ11 -> P | BJ13: =IF(BH13=0,AVERAGE(BF13,BG13),IF(OR(AND(BF13<BG13,BF13>BH13),AND(BF13>BG13,BF13<BH13)),BF13,IF(OR(AND(BG13<BF13,BG13>BH13),AND(BG13>BF13,BG13<BH13)),BG13,BH13))) -> 0.06 | BK13: =IF(BH13>BF13,(BH13-BF13),(BF13-BH13)) -> 0.06 | BL13: =IF(BG13>BH13,(BG13-BH13),(BH13-BG13)) -> 0.06 | BM13: =IF(BH13=0,"",IF(BL13=BK13,"50%",IF(BL13>BK13,"CIEN","MMP")))
A14: =Pb!B12 -> 0 | B14: =+Pb!C12 -> 0 | C14: =Pb!D12 -> 0 | F14: =IF(D14=0,AVERAGE(B14,C14),IF(OR(AND(B14<C14,B14>D14),AND(B14>C14,B14<D14)),B14,IF(OR(AND(C14<B14,C14>D14),AND(C14>B14,C14<D14)),C14,D14))) -> 0 | G14: =IF(D14=0,0,IF(D14>B14,(D14-B14),(B14-D14))) -> 0 | H14: =IF(D14=0,0,IF(C14>D14,(C14-D14),(D14-C14))) -> 0 | I14: =IF(D14=0,"",IF(H14=G14,"50%",IF(H14>G14,"CIEN","MMP"))) | J14: =+Pb!I12 -> 0 | K14: =Pb!J12 -> 0 | N14: =IF(L14=0,AVERAGE(J14,K14),IF(OR(AND(J14<K14,J14>L14),AND(J14>K14,J14<L14)),J14,IF(OR(AND(K14<J14,K14>L14),AND(K14>J14,K14<L14)),K14,L14))) -> 0 | O14: =IF(L14=0,0,IF(L14>J14,(L14-J14),(J14-L14))) -> 0 | P14: =IF(L14=0,0,IF(K14>L14,(K14-L14),(L14-K14))) -> 0 | Q14: =IF(L14=0,"",IF(P14=O14,"50%",IF(P14>O14,"CIEN","MMP"))) | R14: =+Pb!O12 -> 0 | S14: =Pb!P12 -> 0 | V14: =IF(T14=0,AVERAGE(R14,S14),IF(OR(AND(R14<S14,R14>T14),AND(R14>S14,R14<T14)),R14,IF(OR(AND(S14<R14,S14>T14),AND(S14>R14,S14<T14)),S14,T14))) -> 0 | W14: =IF(T14=0,0,IF(T14>R14,(T14-R14),(R14-T14))) -> 0 | X14: =IF(T14=0,0,IF(S14>T14,(S14-T14),(T14-S14))) -> 0 | Y14: =IF(T14=0,"",IF(X14=W14,"50%",IF(X14>W14,"CIEN","MMP"))) | Z14: =+Pb!U12 -> 0 | AA14: =Pb!V12 -> 0 | AD14: =IF(AB14=0,AVERAGE(Z14,AA14),IF(OR(AND(Z14<AA14,Z14>AB14),AND(Z14>AA14,Z14<AB14)),Z14,IF(OR(AND(AA14<Z14,AA14>AB14),AND(AA14>Z14,AA14<AB14)),AA14,AB14))) -> 0 | AE14: =IF(AB14>Z14,(AB14-Z14),(Z14-AB14)) -> 0 | AF14: =IF(AA14>AB14,(AA14-AB14),(AB14-AA14)) -> 0 | AG14: =IF(AB14=0,"",IF(AF14=AE14,"50%",IF(AF14>AE14,"CIEN","MMP"))) | AH14: =+Pb!AA12 -> 0 | AI14: =Pb!AB12 -> 0 | AL14: =IF(AJ14=0,AVERAGE(AH14,AI14),IF(OR(AND(AH14<AI14,AH14>AJ14),AND(AH14>AI14,AH14<AJ14)),AH14,IF(OR(AND(AI14<AH14,AI14>AJ14),AND(AI14>AH14,AI14<AJ14)),AI14,AJ14))) -> 0 | AM14: =IF(AJ14>AH14,(AJ14-AH14),(AH14-AJ14)) -> 0 | AN14: =IF(AI14>AJ14,(AI14-AJ14),(AJ14-AI14)) -> 0 | AO14: =IF(AJ14=0,"",IF(AN14=AM14,"50%",IF(AN14>AM14,"CIEN","MMP"))) | AP14: =+Pb!AS12 -> 0 | AQ14: =Pb!AT12 -> 0 | AT14: =IF(AR14=0,AVERAGE(AP14,AQ14),IF(OR(AND(AP14<AQ14,AP14>AR14),AND(AP14>AQ14,AP14<AR14)),AP14,IF(OR(AND(AQ14<AP14,AQ14>AR14),AND(AQ14>AP14,AQ14<AR14)),AQ14,AR14))) -> 0 | AU14: =IF(AR14>AP14,(AR14-AP14),(AP14-AR14)) -> 0 | AV14: =IF(AQ14>AR14,(AQ14-AR14),(AR14-AQ14)) -> 0 | AW14: =IF(AR14=0,"",IF(AV14=AU14,"50%",IF(AV14>AU14,"CIEN","MMP"))) | AX14: =+Pb!AG12 -> 0 | AY14: =Pb!AH12 -> 0 | BB14: =IF(AZ14=0,AVERAGE(AX14,AY14),IF(OR(AND(AX14<AY14,AX14>AZ14),AND(AX14>AY14,AX14<AZ14)),AX14,IF(OR(AND(AY14<AX14,AY14>AZ14),AND(AY14>AX14,AY14<AZ14)),AY14,AZ14))) -> 0 | BC14: =IF(AZ14>AX14,(AZ14-AX14),(AX14-AZ14)) -> 0 | BD14: =IF(AY14>AZ14,(AY14-AZ14),(AZ14-AY14)) -> 0 | BE14: =IF(AZ14=0,"",IF(BD14=BC14,"50%",IF(BD14>BC14,"CIEN","MMP"))) | BF14: =+Pb!AM12 -> 0 | BG14: =Pb!AN12 -> 0 | BJ14: =IF(BH14=0,AVERAGE(BF14,BG14),IF(OR(AND(BF14<BG14,BF14>BH14),AND(BF14>BG14,BF14<BH14)),BF14,IF(OR(AND(BG14<BF14,BG14>BH14),AND(BG14>BF14,BG14<BH14)),BG14,BH14))) -> 0 | BK14: =IF(BH14>BF14,(BH14-BF14),(BF14-BH14)) -> 0 | BL14: =IF(BG14>BH14,(BG14-BH14),(BH14-BG14)) -> 0 | BM14: =IF(BH14=0,"",IF(BL14=BK14,"50%",IF(BL14>BK14,"CIEN","MMP")))
B15: =+Pb!C13 -> 0 | J15: =+Pb!I13 -> 0 | R15: =+Pb!O13 -> 0 | Z15: =+Pb!U13 -> 0 | AH15: =+Pb!AA13 -> 0 | AP15: =+Pb!AS13 -> 0 | AX15: =+Pb!AG13 -> 0 | BF15: =+Pb!AM13 -> 0
B16: =+Pb!C14 -> 0 | J16: =+Pb!I14 -> 0 | R16: =+Pb!O14 -> 0 | Z16: =+Pb!U14 -> 0 | AH16: =+Pb!AA14 -> 0 | AP16: =+Pb!AS14 -> 0 | AX16: =+Pb!AG14 -> 0 | BF16: =+Pb!AM14 -> 0
B17: =+Pb!C15 -> 0 | J17: =+Pb!I15 -> 0 | R17: =+Pb!O15 -> 0 | Z17: =+Pb!U15 -> 0 | AH17: =+Pb!AA15 -> 0 | AP17: =+Pb!AS15 -> 0 | AX17: =+Pb!AG15 -> 0 | BF17: =+Pb!AM15 -> 0
B18: =+Pb!C16 -> 0 | J18: =+Pb!I16 -> 0 | R18: =+Pb!O16 -> 0 | Z18: =+Pb!U16 -> 0 | AH18: =+Pb!AA16 -> 0 | AP18: =+Pb!AS16 -> 0 | AX18: =+Pb!AG16 -> 0 | BF18: =+Pb!AM16 -> 0
B19: =+Pb!C17 -> 0 | J19: =+Pb!I17 -> 0 | R19: =+Pb!O17 -> 0 | Z19: =+Pb!U17 -> 0 | AH19: =+Pb!AA17 -> 0 | AP19: =+Pb!AS17 -> 0 | AX19: =+Pb!AG17 -> 0 | BF19: =+Pb!AM17 -> 0
B20: =+Pb!C18 -> 0 | J20: =+Pb!I18 -> 0 | R20: =+Pb!O18 -> 0 | Z20: =+Pb!U18 -> 0 | AH20: =+Pb!AA18 -> 0 | AP20: =+Pb!AS18 -> 0 | AX20: =+Pb!AG18 -> 0 | BF20: =+Pb!AM18 -> 0
B21: =+Pb!C19 -> 0 | J21: =+Pb!I19 -> 0 | R21: =+Pb!O19 -> 0 | Z21: =+Pb!U19 -> 0 | AH21: =+Pb!AA19 -> 0 | AP21: =+Pb!AS19 -> 0 | AX21: =+Pb!AG19 -> 0 | BF21: =+Pb!AM19 -> 0
B22: =+Pb!C20 -> 0 | J22: =+Pb!I20 -> 0 | R22: =+Pb!O20 -> 0 | Z22: =+Pb!U20 -> 0 | AH22: =+Pb!AA20 -> 0 | AP22: =+Pb!AS20 -> 0 | AX22: =+Pb!AG20 -> 0 | BF22: =+Pb!AM20 -> 0
B23: =+Pb!C21 -> 0 | J23: =+Pb!I21 -> 0 | R23: =+Pb!O21 -> 0 | Z23: =+Pb!U21 -> 0 | AH23: =+Pb!AA21 -> 0 | AP23: =+Pb!AS21 -> 0 | AX23: =+Pb!AG21 -> 0 | BF23: =+Pb!AM21 -> 0
B24: =+Pb!C22 -> 0 | J24: =+Pb!I22 -> 0 | R24: =+Pb!O22 -> 0 | Z24: =+Pb!U22 -> 0 | AH24: =+Pb!AA22 -> 0 | AP24: =+Pb!AS22 -> 0 | AX24: =+Pb!AG22 -> 0 | BF24: =+Pb!AM22 -> 0
A31: No. | B31: Ensayes de ORO gm/ton | G31: Dif. Vs Tercero | I31: Paga | J31: Ensayes de PLATA gm/ton | O31: Dif. Vs Tercero | Q31: Paga
A32: Lote | B32: MMP | C32: CIEN | D32: Tercero | F32: Pago | G32: MMP | H32: CIEN | I32: Terceria | J32: MMP | K32: CIEN | L32: Tercero | N32: Pago | O32: MMP | P32: CIEN | Q32: Terceria
A33: =Pb!#REF! -> #REF! | B33: =Pb!#REF! -> #REF! | C33: =Pb!#REF! -> #REF! | F33: =IF(D33=0,AVERAGE(B33,C33),IF(OR(AND(B33<C33,B33>D33),AND(B33>C33,B33<D33)),B33,IF(OR(AND(C33<B33,C33>D33),AND(C33>B33,C33<D33)),C33,D33))) -> #REF! | G33: =IF(D33=0,0,IF(D33>B33,(D33-B33),(B33-D33))) -> 0 | H33: =IF(D33=0,0,IF(C33>D33,(C33-D33),(D33-C33))) -> 0 | I33: =IF(D33=0,"",IF(H33=G33,"50%",IF(H33>G33,"CIEN","MMP"))) | J33: =Pb!#REF! -> #REF! | K33: =Pb!#REF! -> #REF! | N33: =IF(L33=0,AVERAGE(J33,K33),IF(OR(AND(J33<K33,J33>L33),AND(J33>K33,J33<L33)),J33,IF(OR(AND(K33<J33,K33>L33),AND(K33>J33,K33<L33)),K33,L33))) -> #REF! | O33: =IF(L33=0,0,IF(L33>J33,(L33-J33),(J33-L33))) -> 0 | P33: =IF(L33=0,0,IF(K33>L33,(K33-L33),(L33-K33))) -> 0 | Q33: =IF(L33=0,"",IF(P33=O33,"50%",IF(P33>O33,"CIEN","MMP")))
A34: =Pb!#REF! -> #REF! | B34: =Pb!#REF! -> #REF! | C34: =Pb!#REF! -> #REF! | F34: =IF(D34=0,AVERAGE(B34,C34),IF(OR(AND(B34<C34,B34>D34),AND(B34>C34,B34<D34)),B34,IF(OR(AND(C34<B34,C34>D34),AND(C34>B34,C34<D34)),C34,D34))) -> #REF! | G34: =IF(D34=0,0,IF(D34>B34,(D34-B34),(B34-D34))) -> 0 | H34: =IF(D34=0,0,IF(C34>D34,(C34-D34),(D34-C34))) -> 0 | I34: =IF(D34=0,"",IF(H34=G34,"50%",IF(H34>G34,"CIEN","MMP"))) | J34: =Pb!#REF! -> #REF! | K34: =Pb!#REF! -> #REF! | N34: =IF(L34=0,AVERAGE(J34,K34),IF(OR(AND(J34<K34,J34>L34),AND(J34>K34,J34<L34)),J34,IF(OR(AND(K34<J34,K34>L34),AND(K34>J34,K34<L34)),K34,L34))) -> #REF! | O34: =IF(L34=0,0,IF(L34>J34,(L34-J34),(J34-L34))) -> 0 | P34: =IF(L34=0,0,IF(K34>L34,(K34-L34),(L34-K34))) -> 0 | Q34: =IF(L34=0,"",IF(P34=O34,"50%",IF(P34>O34,"CIEN","MMP")))
A35: =Pb!#REF! -> #REF! | B35: =Pb!#REF! -> #REF! | C35: =Pb!#REF! -> #REF! | F35: =IF(D35=0,AVERAGE(B35,C35),IF(OR(AND(B35<C35,B35>D35),AND(B35>C35,B35<D35)),B35,IF(OR(AND(C35<B35,C35>D35),AND(C35>B35,C35<D35)),C35,D35))) -> #REF! | G35: =IF(D35=0,0,IF(D35>B35,(D35-B35),(B35-D35))) -> 0 | H35: =IF(D35=0,0,IF(C35>D35,(C35-D35),(D35-C35))) -> 0 | I35: =IF(D35=0,"",IF(H35=G35,"50%",IF(H35>G35,"CIEN","MMP"))) | J35: =Pb!#REF! -> #REF! | K35: =Pb!#REF! -> #REF! | N35: =IF(L35=0,AVERAGE(J35,K35),IF(OR(AND(J35<K35,J35>L35),AND(J35>K35,J35<L35)),J35,IF(OR(AND(K35<J35,K35>L35),AND(K35>J35,K35<L35)),K35,L35))) -> #REF! | O35: =IF(L35=0,0,IF(L35>J35,(L35-J35),(J35-L35))) -> 0 | P35: =IF(L35=0,0,IF(K35>L35,(K35-L35),(L35-K35))) -> 0 | Q35: =IF(L35=0,"",IF(P35=O35,"50%",IF(P35>O35,"CIEN","MMP")))
A36: =Pb!#REF! -> #REF! | B36: =Pb!#REF! -> #REF! | C36: =Pb!#REF! -> #REF! | F36: =IF(D36=0,AVERAGE(B36,C36),IF(OR(AND(B36<C36,B36>D36),AND(B36>C36,B36<D36)),B36,IF(OR(AND(C36<B36,C36>D36),AND(C36>B36,C36<D36)),C36,D36))) -> #REF! | G36: =IF(D36=0,0,IF(D36>B36,(D36-B36),(B36-D36))) -> 0 | H36: =IF(D36=0,0,IF(C36>D36,(C36-D36),(D36-C36))) -> 0 | I36: =IF(D36=0,"",IF(H36=G36,"50%",IF(H36>G36,"CIEN","MMP"))) | J36: =Pb!#REF! -> #REF! | K36: =Pb!#REF! -> #REF! | N36: =IF(L36=0,AVERAGE(J36,K36),IF(OR(AND(J36<K36,J36>L36),AND(J36>K36,J36<L36)),J36,IF(OR(AND(K36<J36,K36>L36),AND(K36>J36,K36<L36)),K36,L36))) -> #REF! | O36: =IF(L36=0,0,IF(L36>J36,(L36-J36),(J36-L36))) -> 0 | P36: =IF(L36=0,0,IF(K36>L36,(K36-L36),(L36-K36))) -> 0 | Q36: =IF(L36=0,"",IF(P36=O36,"50%",IF(P36>O36,"CIEN","MMP")))
A37: =Pb!#REF! -> #REF! | B37: =Pb!#REF! -> #REF! | C37: =Pb!#REF! -> #REF! | F37: =IF(D37=0,AVERAGE(B37,C37),IF(OR(AND(B37<C37,B37>D37),AND(B37>C37,B37<D37)),B37,IF(OR(AND(C37<B37,C37>D37),AND(C37>B37,C37<D37)),C37,D37))) -> #REF! | G37: =IF(D37=0,0,IF(D37>B37,(D37-B37),(B37-D37))) -> 0 | H37: =IF(D37=0,0,IF(C37>D37,(C37-D37),(D37-C37))) -> 0 | I37: =IF(D37=0,"",IF(H37=G37,"50%",IF(H37>G37,"CIEN","MMP"))) | J37: =Pb!#REF! -> #REF! | K37: =Pb!#REF! -> #REF! | N37: =IF(L37=0,AVERAGE(J37,K37),IF(OR(AND(J37<K37,J37>L37),AND(J37>K37,J37<L37)),J37,IF(OR(AND(K37<J37,K37>L37),AND(K37>J37,K37<L37)),K37,L37))) -> #REF! | O37: =IF(L37=0,0,IF(L37>J37,(L37-J37),(J37-L37))) -> 0 | P37: =IF(L37=0,0,IF(K37>L37,(K37-L37),(L37-K37))) -> 0 | Q37: =IF(L37=0,"",IF(P37=O37,"50%",IF(P37>O37,"CIEN","MMP")))
A38: =Pb!#REF! -> #REF! | B38: =Pb!#REF! -> #REF! | C38: =Pb!#REF! -> #REF! | F38: =IF(D38=0,AVERAGE(B38,C38),IF(OR(AND(B38<C38,B38>D38),AND(B38>C38,B38<D38)),B38,IF(OR(AND(C38<B38,C38>D38),AND(C38>B38,C38<D38)),C38,D38))) -> #REF! | G38: =IF(D38=0,0,IF(D38>B38,(D38-B38),(B38-D38))) -> 0 | H38: =IF(D38=0,0,IF(C38>D38,(C38-D38),(D38-C38))) -> 0 | I38: =IF(D38=0,"",IF(H38=G38,"50%",IF(H38>G38,"CIEN","MMP"))) | J38: =Pb!#REF! -> #REF! | K38: =Pb!#REF! -> #REF! | N38: =IF(L38=0,AVERAGE(J38,K38),IF(OR(AND(J38<K38,J38>L38),AND(J38>K38,J38<L38)),J38,IF(OR(AND(K38<J38,K38>L38),AND(K38>J38,K38<L38)),K38,L38))) -> #REF! | O38: =IF(L38=0,0,IF(L38>J38,(L38-J38),(J38-L38))) -> 0 | P38: =IF(L38=0,0,IF(K38>L38,(K38-L38),(L38-K38))) -> 0 | Q38: =IF(L38=0,"",IF(P38=O38,"50%",IF(P38>O38,"CIEN","MMP")))
A39: =Pb!#REF! -> #REF! | B39: =Pb!#REF! -> #REF! | C39: =Pb!#REF! -> #REF! | F39: =IF(D39=0,AVERAGE(B39,C39),IF(OR(AND(B39<C39,B39>D39),AND(B39>C39,B39<D39)),B39,IF(OR(AND(C39<B39,C39>D39),AND(C39>B39,C39<D39)),C39,D39))) -> #REF! | G39: =IF(D39=0,0,IF(D39>B39,(D39-B39),(B39-D39))) -> 0 | H39: =IF(D39=0,0,IF(C39>D39,(C39-D39),(D39-C39))) -> 0 | I39: =IF(D39=0,"",IF(H39=G39,"50%",IF(H39>G39,"CIEN","MMP"))) | J39: =Pb!#REF! -> #REF! | K39: =Pb!#REF! -> #REF! | N39: =IF(L39=0,AVERAGE(J39,K39),IF(OR(AND(J39<K39,J39>L39),AND(J39>K39,J39<L39)),J39,IF(OR(AND(K39<J39,K39>L39),AND(K39>J39,K39<L39)),K39,L39))) -> #REF! | O39: =IF(L39=0,0,IF(L39>J39,(L39-J39),(J39-L39))) -> 0 | P39: =IF(L39=0,0,IF(K39>L39,(K39-L39),(L39-K39))) -> 0 | Q39: =IF(L39=0,"",IF(P39=O39,"50%",IF(P39>O39,"CIEN","MMP")))
A40: =Pb!#REF! -> #REF! | B40: =Pb!#REF! -> #REF! | C40: =Pb!#REF! -> #REF! | F40: =IF(D40=0,AVERAGE(B40,C40),IF(OR(AND(B40<C40,B40>D40),AND(B40>C40,B40<D40)),B40,IF(OR(AND(C40<B40,C40>D40),AND(C40>B40,C40<D40)),C40,D40))) -> #REF! | G40: =IF(D40=0,0,IF(D40>B40,(D40-B40),(B40-D40))) -> 0 | H40: =IF(D40=0,0,IF(C40>D40,(C40-D40),(D40-C40))) -> 0 | I40: =IF(D40=0,"",IF(H40=G40,"50%",IF(H40>G40,"CIEN","MMP"))) | J40: =Pb!#REF! -> #REF! | K40: =Pb!#REF! -> #REF! | N40: =IF(L40=0,AVERAGE(J40,K40),IF(OR(AND(J40<K40,J40>L40),AND(J40>K40,J40<L40)),J40,IF(OR(AND(K40<J40,K40>L40),AND(K40>J40,K40<L40)),K40,L40))) -> #REF! | O40: =IF(L40=0,0,IF(L40>J40,(L40-J40),(J40-L40))) -> 0 | P40: =IF(L40=0,0,IF(K40>L40,(K40-L40),(L40-K40))) -> 0 | Q40: =IF(L40=0,"",IF(P40=O40,"50%",IF(P40>O40,"CIEN","MMP")))
A41: =Pb!#REF! -> #REF! | B41: =Pb!#REF! -> #REF! | C41: =Pb!#REF! -> #REF! | F41: =IF(D41=0,AVERAGE(B41,C41),IF(OR(AND(B41<C41,B41>D41),AND(B41>C41,B41<D41)),B41,IF(OR(AND(C41<B41,C41>D41),AND(C41>B41,C41<D41)),C41,D41))) -> #REF! | G41: =IF(D41=0,0,IF(D41>B41,(D41-B41),(B41-D41))) -> 0 | H41: =IF(D41=0,0,IF(C41>D41,(C41-D41),(D41-C41))) -> 0 | I41: =IF(D41=0,"",IF(H41=G41,"50%",IF(H41>G41,"CIEN","MMP"))) | J41: =Pb!#REF! -> #REF! | K41: =Pb!#REF! -> #REF! | N41: =IF(L41=0,AVERAGE(J41,K41),IF(OR(AND(J41<K41,J41>L41),AND(J41>K41,J41<L41)),J41,IF(OR(AND(K41<J41,K41>L41),AND(K41>J41,K41<L41)),K41,L41))) -> #REF! | O41: =IF(L41=0,0,IF(L41>J41,(L41-J41),(J41-L41))) -> 0 | P41: =IF(L41=0,0,IF(K41>L41,(K41-L41),(L41-K41))) -> 0 | Q41: =IF(L41=0,"",IF(P41=O41,"50%",IF(P41>O41,"CIEN","MMP")))
A42: =Pb!#REF! -> #REF! | B42: =Pb!#REF! -> #REF! | C42: =Pb!#REF! -> #REF! | F42: =IF(D42=0,AVERAGE(B42,C42),IF(OR(AND(B42<C42,B42>D42),AND(B42>C42,B42<D42)),B42,IF(OR(AND(C42<B42,C42>D42),AND(C42>B42,C42<D42)),C42,D42))) -> #REF! | G42: =IF(D42=0,0,IF(D42>B42,(D42-B42),(B42-D42))) -> 0 | H42: =IF(D42=0,0,IF(C42>D42,(C42-D42),(D42-C42))) -> 0 | I42: =IF(D42=0,"",IF(H42=G42,"50%",IF(H42>G42,"CIEN","MMP"))) | J42: =Pb!#REF! -> #REF! | K42: =Pb!#REF! -> #REF! | N42: =IF(L42=0,AVERAGE(J42,K42),IF(OR(AND(J42<K42,J42>L42),AND(J42>K42,J42<L42)),J42,IF(OR(AND(K42<J42,K42>L42),AND(K42>J42,K42<L42)),K42,L42))) -> #REF! | O42: =IF(L42=0,0,IF(L42>J42,(L42-J42),(J42-L42))) -> 0 | P42: =IF(L42=0,0,IF(K42>L42,(K42-L42),(L42-K42))) -> 0 | Q42: =IF(L42=0,"",IF(P42=O42,"50%",IF(P42>O42,"CIEN","MMP")))
A43: =Pb!#REF! -> #REF! | B43: =Pb!#REF! -> #REF! | C43: =Pb!#REF! -> #REF! | F43: =IF(D43=0,AVERAGE(B43,C43),IF(OR(AND(B43<C43,B43>D43),AND(B43>C43,B43<D43)),B43,IF(OR(AND(C43<B43,C43>D43),AND(C43>B43,C43<D43)),C43,D43))) -> #REF! | G43: =IF(D43=0,0,IF(D43>B43,(D43-B43),(B43-D43))) -> 0 | H43: =IF(D43=0,0,IF(C43>D43,(C43-D43),(D43-C43))) -> 0 | I43: =IF(D43=0,"",IF(H43=G43,"50%",IF(H43>G43,"CIEN","MMP"))) | J43: =Pb!#REF! -> #REF! | K43: =Pb!#REF! -> #REF! | N43: =IF(L43=0,AVERAGE(J43,K43),IF(OR(AND(J43<K43,J43>L43),AND(J43>K43,J43<L43)),J43,IF(OR(AND(K43<J43,K43>L43),AND(K43>J43,K43<L43)),K43,L43))) -> #REF! | O43: =IF(L43=0,0,IF(L43>J43,(L43-J43),(J43-L43))) -> 0 | P43: =IF(L43=0,0,IF(K43>L43,(K43-L43),(L43-K43))) -> 0 | Q43: =IF(L43=0,"",IF(P43=O43,"50%",IF(P43>O43,"CIEN","MMP")))
A44: =Pb!#REF! -> #REF! | B44: =Pb!#REF! -> #REF! | C44: =Pb!#REF! -> #REF! | F44: =IF(D44=0,AVERAGE(B44,C44),IF(OR(AND(B44<C44,B44>D44),AND(B44>C44,B44<D44)),B44,IF(OR(AND(C44<B44,C44>D44),AND(C44>B44,C44<D44)),C44,D44))) -> #REF! | G44: =IF(D44=0,0,IF(D44>B44,(D44-B44),(B44-D44))) -> 0 | H44: =IF(D44=0,0,IF(C44>D44,(C44-D44),(D44-C44))) -> 0 | I44: =IF(D44=0,"",IF(H44=G44,"50%",IF(H44>G44,"CIEN","MMP"))) | J44: =Pb!#REF! -> #REF! | K44: =Pb!#REF! -> #REF! | N44: =IF(L44=0,AVERAGE(J44,K44),IF(OR(AND(J44<K44,J44>L44),AND(J44>K44,J44<L44)),J44,IF(OR(AND(K44<J44,K44>L44),AND(K44>J44,K44<L44)),K44,L44))) -> #REF! | O44: =IF(L44=0,0,IF(L44>J44,(L44-J44),(J44-L44))) -> 0 | P44: =IF(L44=0,0,IF(K44>L44,(K44-L44),(L44-K44))) -> 0 | Q44: =IF(L44=0,"",IF(P44=O44,"50%",IF(P44>O44,"CIEN","MMP")))
A45: =Pb!#REF! -> #REF! | B45: =Pb!#REF! -> #REF! | C45: =Pb!#REF! -> #REF! | F45: =IF(D45=0,AVERAGE(B45,C45),IF(OR(AND(B45<C45,B45>D45),AND(B45>C45,B45<D45)),B45,IF(OR(AND(C45<B45,C45>D45),AND(C45>B45,C45<D45)),C45,D45))) -> #REF! | G45: =IF(D45=0,0,IF(D45>B45,(D45-B45),(B45-D45))) -> 0 | H45: =IF(D45=0,0,IF(C45>D45,(C45-D45),(D45-C45))) -> 0 | I45: =IF(D45=0,"",IF(H45=G45,"50%",IF(H45>G45,"CIEN","MMP"))) | J45: =Pb!#REF! -> #REF! | K45: =Pb!#REF! -> #REF! | N45: =IF(L45=0,AVERAGE(J45,K45),IF(OR(AND(J45<K45,J45>L45),AND(J45>K45,J45<L45)),J45,IF(OR(AND(K45<J45,K45>L45),AND(K45>J45,K45<L45)),K45,L45))) -> #REF! | O45: =IF(L45=0,0,IF(L45>J45,(L45-J45),(J45-L45))) -> 0 | P45: =IF(L45=0,0,IF(K45>L45,(K45-L45),(L45-K45))) -> 0 | Q45: =IF(L45=0,"",IF(P45=O45,"50%",IF(P45>O45,"CIEN","MMP")))

Sheet Ens. Zinc
A1: MINERA MEXICANA LA CIENEGA, S.A. DE C.V.
A5: COMPARACION DE ENSAYES
A7: Lotes cerrados en 2025.
A9: CONCENTRADO DE ZINC
C10: Au | D10: Ag | E10: Zn | F10: Cd | G10: As | H10: Fe | I10: MgO | J10: Insol
C11: Gms/Ton | D11: Kgs/Ton | E11: % | F11: % | G11: % | H11: % | I11: % | J11: %
A12: LOTE MMP | B12: LOTE MINA
A13: =[1]Zinc!$A9 -> 0 | B13: =[1]Zinc!$B9 -> 0 | C13: =[1]Zinc!C9 -> 0 | D13: =[1]Zinc!F9 -> 0 | E13: =[1]Zinc!I9 -> 0 | F13: =[1]Zinc!L9 -> 0 | G13: =[1]Zinc!R9 -> 0 | H13: =[1]Zinc!O9 -> 0 | I13: =[1]Zinc!U9 -> 0 | J13: =[1]Zinc!X9 -> 0
A14: =[1]Zinc!$A10 -> 0 | B14: =[1]Zinc!$B10 -> 0 | C14: =[1]Zinc!C10 -> 0 | D14: =[1]Zinc!F10 -> 0 | E14: =[1]Zinc!I10 -> 0 | F14: =[1]Zinc!L10 -> 0 | G14: =[1]Zinc!R10 -> 0 | H14: =[1]Zinc!O10 -> 0 | I14: =[1]Zinc!U10 -> 0 | J14: =[1]Zinc!X10 -> 0
D19: Ing. Laura D. Medina Carranza
D20: Gerencia Administrativa OFSA

Sheet Zn
A1: ='Ens. Zinc'!A1:G1 -> MINERA MEXICANA LA CIENEGA, S.A. DE C.V.
A2: CUADRO PARA DETERMINAR LOS ANALISIS EN CONJUNTO
A3: ='Ens. Zinc'!$A$7:$G$7 -> Lotes cerrados en 2025.
A4: CONCENTRADO DE ZINC
A6: LOTE | D6: ENSAYES DE ORO | J6: ENSAYES DE PLATA KGS/TON | P6: ENSAYES DE ZINC | V6: ENSAYES DE CADMIO | AB6: ENSAYES DE ARSÉNICO (Libre 0.1 %) | AH6: ENSAYES DE FIERRO (Libre 8.0%) | AN6: ENSAYES DE OXIDO DE MAGNESIO ( LIBRE .1 %) | AT6: ENSAYES DE INSOLUBLES
D7: Met-Mex | E7: Ciénega | F7: Dif | G7: L.P. | H7: INT. | I7: Final | J7: Met-Mex | K7: Ciénega | L7: Dif | M7: L.P. | N7: INT. | O7: Final | P7: Met-Mex | Q7: Ciénega | R7: Dif | S7: L.P. | T7: INT. | U7: Final | V7: Met-Mex | W7: Ciénega | X7: Dif | Y7: L.P. | Z7: INT. | AA7: Final | AB7: Met-Mex | AC7: Ciénega | AD7: Dif | AE7: L.P. | AF7: INT. | AG7: Final | AH7: Met-Mex | AI7: Ciénega | AJ7: Dif | AK7: L.P. | AL7: INT. | AM7: Final | AN7: Met-Mex | AO7: Ciénega | AP7: Dif | AQ7: L.P. | AR7: INT. | AS7: Final | AT7: Met-Mex | AU7: Ciénega | AV7: Dif | AW7: L.P. | AX7: INT. | AY7: Final
B8: ='Ens. Zinc'!B13 -> 0 | E8: ='Ens. Zinc'!C13 -> 0 | F8: =ROUND(ABS(D8-E8),2) -> 0 | G8: =IF(E8<=10,0.3,IF(E8>10,0.4)) -> 0.3 | H8: =IF(F8<=G8,"P","T") -> P | I8: =IF(ISBLANK(D8)," ",IF(F8<=G8,AVERAGE(D8:E8),0)) | K8: ='Ens. Zinc'!D13 -> 0 | L8: =ROUND(ABS(J8-K8),3) -> 0 | M8: =IF(K8>=0.08,0.015,0) -> 0 | N8: =IF(L8<=M8,"P","T") -> P | O8: =IF(ISBLANK(J8)," ",IF(L8<=M8,AVERAGE(J8:K8),0)) | Q8: ='Ens. Zinc'!E13 -> 0 | R8: =ROUND(ABS(P8-Q8),2) -> 0 | S8: =IF(Q8>=40,0.5,0) -> 0 | T8: =IF(R8<=S8,"P","T") -> P | U8: =IF(ISBLANK(P8)," ",IF(R8>=S8,AVERAGE(P8:Q8),0)) | W8: ='Ens. Zinc'!F13 -> 0 | X8: =ROUND(ABS(V8-W8),2) -> 0 | Y8: =IF(W8<=1,0.03,0) -> 0.03 | Z8: =IF(X8<=Y8,"P","T") -> P | AA8: =IF(ISBLANK(V8)," ",IF(X8<=Y8,AVERAGE(V8:W8),0)) | AC8: ='Ens. Zinc'!G13 -> 0 | AD8: =ROUND(ABS(AB8-AC8),2) -> 0 | AE8: =IF(AC8<=1,0.02,0) -> 0.02 | AF8: =IF(AD8<=AE8,"P","T") -> P | AG8: =IF(ISBLANK(AB8)," ",IF(AD8<=AE8,AVERAGE(AB8:AC8),0)) | AI8: ='Ens. Zinc'!H13 -> 0 | AJ8: =ROUND(ABS(AH8-AI8),2) -> 0 | AK8: =IF(AI8<=10,0.3,0) -> 0.3 | AL8: =IF(AJ8<=AK8,"P","T") -> P | AM8: =IF(ISBLANK(AH8)," ",IF(AL8="P",AVERAGE(AH8,AI8),0)) | AO8: 0 | AP8: =ROUND(ABS(AN8-AO8),2) -> 0 | AQ8: 0.02 | AR8: =IF(AP8<=AQ8,"P","T") -> P | AS8: =IF(ISBLANK(AN8)," ",IF(AR8="P",AVERAGE(AN8,AO8),0)) | AU8: ='Ens. Zinc'!J13 -> 0 | AV8: =ROUND(ABS(AT8-AU8),2) -> 0 | AW8: =IF(AU8>=5,0.3,0) -> 0 | AX8: =IF(AV8<=AW8,"P","T") -> P | AY8: =IF(ISBLANK(AT8)," ",IF(AX8="P",AVERAGE(AT8,AU8),0))
B9: ='Ens. Zinc'!B14 -> 0 | E9: ='Ens. Zinc'!C14 -> 0 | F9: =ROUND(ABS(D9-E9),2) -> 0 | G9: =IF(E9<=10,0.3,IF(E9>10,0.4)) -> 0.3 | H9: =IF(F9<=G9,"P","T") -> P | I9: =IF(ISBLANK(D9)," ",IF(F9<=G9,AVERAGE(D9:E9),0)) | K9: ='Ens. Zinc'!D14 -> 0 | L9: =ROUND(ABS(J9-K9),3) -> 0 | M9: =IF(K9>=0.08,0.015,0) -> 0 | N9: =IF(L9<=M9,"P","T") -> P | O9: =IF(ISBLANK(J9)," ",IF(L9<=M9,AVERAGE(J9:K9),0)) | Q9: ='Ens. Zinc'!E14 -> 0 | R9: =ROUND(ABS(P9-Q9),2) -> 0 | S9: =IF(Q9>=40,0.5,0) -> 0 | T9: =IF(R9<=S9,"P","T") -> P | U9: =IF(ISBLANK(P9)," ",IF(R9<=S9,AVERAGE(P9:Q9),0)) | W9: ='Ens. Zinc'!F14 -> 0 | X9: =ROUND(ABS(V9-W9),2) -> 0 | Y9: =IF(W9<=1,0.03,0) -> 0.03 | Z9: =IF(X9<=Y9,"P","T") -> P | AA9: =IF(ISBLANK(V9)," ",IF(X9<=Y9,AVERAGE(V9:W9),0)) | AC9: ='Ens. Zinc'!G14 -> 0 | AD9: =ROUND(ABS(AB9-AC9),2) -> 0 | AE9: =IF(AC9<=1,0.02,0) -> 0.02 | AF9: =IF(AD9<=AE9,"P","T") -> P | AG9: =IF(ISBLANK(AB9)," ",IF(AD9<=AE9,AVERAGE(AB9:AC9),0)) | AI9: ='Ens. Zinc'!H14 -> 0 | AJ9: =ROUND(ABS(AH9-AI9),2) -> 0 | AK9: =IF(AI9<=10,0.3,0) -> 0.3 | AL9: =IF(AJ9<=AK9,"P","T") -> P | AM9: =IF(ISBLANK(AH9)," ",IF(AL9="P",AVERAGE(AH9,AI9),0)) | AO9: ='Ens. Zinc'!I14 -> 0 | AP9: =ROUND(ABS(AN9-AO9),2) -> 0 | AQ9: 0.02 | AR9: =IF(AP9<=AQ9,"P","T") -> P | AS9: =IF(ISBLANK(AN9)," ",IF(AR9="P",AVERAGE(AN9,AO9),0)) | AU9: ='Ens. Zinc'!J14 -> 0 | AV9: =ROUND(ABS(AT9-AU9),2) -> 0 | AW9: =IF(AU9>=5,0.3,0) -> 0 | AX9: =IF(AV9<=AW9,"P","T") -> P | AY9: =IF(ISBLANK(AT9)," ",IF(AX9="P",AVERAGE(AT9,AU9),0))
B10: ='Ens. Zinc'!#REF! -> #REF! | E10: ='Ens. Zinc'!#REF! -> #REF! | F10: =ROUND(ABS(D10-E10),2) -> #REF! | G10: =IF(E10<=10,0.3,IF(E10>10,0.4)) -> #REF! | H10: =IF(F10<=G10,"P","T") -> #REF! | I10: =IF(ISBLANK(D10)," ",IF(F10<=G10,AVERAGE(D10:E10),0)) | K10: ='Ens. Zinc'!#REF! -> #REF! | L10: =ROUND(ABS(J10-K10),3) -> #REF! | M10: =IF(K10>=0.08,0.015,0) -> #REF! | N10: =IF(L10<=M10,"P","T") -> #REF! | O10: =IF(ISBLANK(J10)," ",IF(L10<=M10,AVERAGE(J10:K10),0)) | Q10: ='Ens. Zinc'!#REF! -> #REF! | R10: =ROUND(ABS(P10-Q10),2) -> #REF! | S10: =IF(Q10>=40,0.5,0) -> #REF! | T10: =IF(R10<=S10,"P","T") -> #REF! | U10: =IF(ISBLANK(P10)," ",IF(R10<=S10,AVERAGE(P10:Q10),0)) | W10: ='Ens. Zinc'!#REF! -> #REF! | X10: =ROUND(ABS(V10-W10),2) -> #REF! | Y10: =IF(W10<=1,0.03,0) -> #REF! | Z10: =IF(X10<=Y10,"P","T") -> #REF! | AA10: =IF(ISBLANK(V10)," ",IF(X10<=Y10,AVERAGE(V10:W10),0)) | AC10: ='Ens. Zinc'!#REF! -> #REF! | AD10: =ROUND(ABS(AB10-AC10),2) -> #REF! | AE10: =IF(AC10<=1,0.03,0) -> #REF! | AF10: =IF(AD10<=AE10,"P","T") -> #REF! | AG10: =IF(ISBLANK(AB10)," ",IF(AD10<=AE10,AVERAGE(AB10:AC10),0)) | AI10: ='Ens. Zinc'!#REF! -> #REF! | AJ10: =ROUND(ABS(AH10-AI10),2) -> #REF! | AK10: =IF(AI10<=10,0.3,0) -> #REF! | AL10: =IF(AJ10<>AK10,"P","T") -> #REF! | AM10: =IF(ISBLANK(AH10)," ",IF(AL10="P",AVERAGE(AH10,AI10),0)) | AO10: ='Ens. Zinc'!#REF! -> #REF! | AP10: =ROUND(ABS(AN10-AO10),2) -> #REF! | AQ10: 0.02 | AR10: =IF(AP10<=AQ10,"P","T") -> #REF! | AS10: =IF(ISBLANK(AN10)," ",IF(AR10="P",AVERAGE(AN10,AO10),0)) | AU10: ='Ens. Zinc'!#REF! -> #REF! | AV10: =ROUND(ABS(AT10-AU10),2) -> #REF! | AW10: =IF(AU10>=5,0.3,0) -> #REF! | AX10: =IF(AV10<=AW10,"P","T") -> #REF! | AY10: =IF(ISBLANK(AT10)," ",IF(AX10="P",AVERAGE(AT10,AU10),0))

Sheet Terc. Zinc
A1: MINERA MEXICANA LA CIÉNEGA, S.A. DE C.V.
A3: CUADRO PARA DETERMINAR DIFERENCIAS EN ENSAYES COMPARADOS
A6: =+Pb!A3 -> Lotes cerrados febrero 2026.
T7: ZINC
A8: No. | B8: Ensayes de ORO gm/ton | G8: Dif. Vs Tercero | I8: Paga | J8: Ensayes de PLATA gm/ton | O8: Dif. Vs Tercero | Q8: Paga | R8: Ensayes de ZINC % | W8: Dif. Vs Tercero | Y8: Paga | Z8: Ensayes de MgO | AE8: Dif. Vs Tercero | AG8: Paga | AH8: Ensayes de CADMIO % | AM8: Dif. Vs Tercero | AO8: Paga | AP8: Ensayes de FIERRO % | AU8: Dif. Vs Tercero | AW8: Paga | AX8: Ensayes de INSOLUBLES % | BC8: Dif. Vs Tercero | BE8: Paga | BF8: Ensayes de ARSENICO % | BK8: Dif. Vs Tercero | BM8: Paga | BP8: ALEX STEWART
A9: Lote | B9: MMP | C9: CIEN | D9: Tercero | E9: INT. | F9: Pago | G9: MMP | H9: CIEN | I9: Terceria | J9: MMP | K9: CIEN | L9: Tercero | M9: INT. | N9: Pago | O9: MMP | P9: CIEN | Q9: Terceria | R9: MMP | S9: CIEN | T9: Tercero | U9: INT. | V9: Pago | W9: MMP | X9: CIEN | Y9: Terceria | Z9: MMP | AA9: CIEN | AB9: Tercero | AC9: INT. | AD9: Pago | AE9: MMP | AF9: CIEN | AG9: Terceria | AH9: MMP | AI9: CIEN | AJ9: Tercero | AK9: INT. | AL9: Pago | AM9: MMP | AN9: CIEN | AO9: Terceria | AP9: MMP | AQ9: CIEN | AR9: Tercero | AS9: INT. | AT9: Pago | AU9: MMP | AV9: CIEN | AW9: Terceria | AX9: MMP | AY9: CIEN | AZ9: Tercero | BA9: INT. | BB9: Pago | BC9: MMP | BD9: CIEN | BE9: Terceria | BF9: MMP | BG9: CIEN | BH9: Tercero | BI9: INT. | BJ9: Pago | BK9: MMP | BL9: CIEN | BM9: Terceria | BP9: LIM | BS9: NEGRITAS
A10: =+Zn!B8 -> 0 | B10: =+Zn!D8 -> 0 | C10: =+Zn!E8 -> 0 | E10: =+Zn!H8 -> P | F10: =IF(D10=0,AVERAGE(B10,C10),IF(OR(AND(B10<C10,B10>D10),AND(B10>C10,B10<D10)),B10,IF(OR(AND(C10<B10,C10>D10),AND(C10>B10,C10<D10)),C10,D10))) -> 0 | G10: =IF(D10=0,0,IF(D10>B10,(D10-B10),(B10-D10))) -> 0 | H10: =IF(D10=0,0,IF(C10>D10,(C10-D10),(D10-C10))) -> 0 | I10: =IF(D10=0,"",IF(H10=G10,"50%",IF(H10>G10,"CIEN","MMP"))) | J10: =+Zn!J8 -> 0 | K10: =+Zn!K8 -> 0 | M10: =+Zn!N8 -> P | N10: =IF(L10=0,AVERAGE(J10,K10),IF(OR(AND(J10<K10,J10>L10),AND(J10>K10,J10<L10)),J10,IF(OR(AND(K10<J10,K10>L10),AND(K10>J10,K10<L10)),K10,L10))) -> 0 | O10: =IF(L10=0,0,IF(L10>J10,(L10-J10),(J10-L10))) -> 0 | P10: =IF(L10=0,0,IF(K10>L10,(K10-L10),(L10-K10))) -> 0 | Q10: =IF(L10=0,"",IF(P10=O10,"50%",IF(P10>O10,"CIEN","MMP"))) | R10: =+Zn!P8 -> 0 | S10: =+Zn!Q8 -> 0 | U10: =+Zn!T8 -> P | V10: =IF(T10=0,AVERAGE(R10,S10),IF(OR(AND(R10<S10,R10>T10),AND(R10>S10,R10<T10)),R10,IF(OR(AND(S10<R10,S10>T10),AND(S10>R10,S10<T10)),S10,T10))) -> 0 | W10: =IF(T10=0,0,IF(T10>R10,(T10-R10),(R10-T10))) -> 0 | X10: =IF(T10=0,0,IF(S10>T10,(S10-T10),(T10-S10))) -> 0 | Y10: =IF(T10=0,"",IF(X10=W10,"50%",IF(X10>W10,"CIEN","MMP"))) | Z10: =+Zn!AN8 -> 0 | AA10: =+Zn!AO8 -> 0 | AC10: =+Zn!AR8 -> P | AD10: =IF(AB10=0,AVERAGE(Z10,AA10),IF(OR(AND(Z10<AA10,Z10>AB10),AND(Z10>AA10,Z10<AB10)),Z10,IF(OR(AND(AA10<Z10,AA10>AB10),AND(AA10>Z10,AA10<AB10)),AA10,AB10))) -> 0 | AE10: =IF(Z10>AB10,(Z10-AB10),(AB10-Z10)) -> 0 | AF10: =IF(AA10>AB10,(AA10-AB10),(AB10-AA10)) -> 0 | AG10: =IF(AB10=0,"",IF(AF10=AE10,"50%",IF(AF10>AE10,"CIEN","MMP"))) | AH10: =+Zn!V8 -> 0 | AI10: =+Zn!W8 -> 0 | AK10: =+Zn!Z8 -> P | AL10: =IF(AJ10=0,AVERAGE(AH10,AI10),IF(OR(AND(AH10<AI10,AH10>AJ10),AND(AH10>AI10,AH10<AJ10)),AH10,IF(OR(AND(AI10<AH10,AI10>AJ10),AND(AI10>AH10,AI10<AJ10)),AI10,AJ10))) -> 0 | AM10: =IF(AJ10>AH10,(AJ10-AH10),(AH10-AJ10)) -> 0 | AN10: =IF(AI10>AJ10,(AI10-AJ10),(AJ10-AI10)) -> 0 | AO10: =IF(AJ10=0,"",IF(AN10=AM10,"50%",IF(AN10>AM10,"CIEN","MMP"))) | AP10: =+Zn!AH8 -> 0 | AQ10: =+Zn!AI8 -> 0 | AS10: =+Zn!AL8 -> P | AT10: =IF(AR10=0,AVERAGE(AP10,AQ10),IF(OR(AND(AP10<AQ10,AP10>AR10),AND(AP10>AQ10,AP10<AR10)),AP10,IF(OR(AND(AQ10<AP10,AQ10>AR10),AND(AQ10>AP10,AQ10<AR10)),AQ10,AR10))) -> 0 | AU10: =IF(AR10>AP10,(AR10-AP10),(AP10-AR10)) -> 0 | AV10: =IF(AQ10>AR10,(AQ10-AR10),(AR10-AQ10)) -> 0 | AW10: =IF(AR10=0,"",IF(AV10=AU10,"50%",IF(AV10>AU10,"CIEN","MMP"))) | AX10: =+Zn!AT8 -> 0 | AY10: =+Zn!AU8 -> 0 | BA10: =+Zn!AX8 -> P | BB10: =IF(AZ10=0,AVERAGE(AX10,AY10),IF(OR(AND(AX10<AY10,AX10>AZ10),AND(AX10>AY10,AX10<AZ10)),AX10,IF(OR(AND(AY10<AX10,AY10>AZ10),AND(AY10>AX10,AY10<AZ10)),AY10,AZ10))) -> 0 | BC10: =IF(AZ10>AX10,(AZ10-AX10),(AX10-AZ10)) -> 0 | BD10: =IF(AY10>AZ10,(AY10-AZ10),(AZ10-AY10)) -> 0 | BE10: =IF(AZ10=0,"",IF(BD10=BC10,"50%",IF(BD10>BC10,"CIEN","MMP"))) | BF10: =+Zn!AB8 -> 0 | BG10: =+Zn!AC8 -> 0 | BI10: =+Zn!AF8 -> P | BJ10: =IF(BH10=0,AVERAGE(BF10,BG10),IF(OR(AND(BF10<BG10,BF10>BH10),AND(BF10>BG10,BF10<BH10)),BF10,IF(OR(AND(BG10<BF10,BG10>BH10),AND(BG10>BF10,BG10<BH10)),BG10,BH10))) -> 0 | BK10: =IF(BH10>BF10,(BH10-BF10),(BF10-BH10)) -> 0 | BL10: =IF(BG10>BH10,(BG10-BH10),(BH10-BG10)) -> 0 | BM10: =IF(BH10=0,"",IF(BL10=BK10,"50%",IF(BL10>BK10,"CIEN","MMP"))) | BP10: COURTADE | BS10: KURSIVA
A11: =+Zn!B9 -> 0 | B11: =+Zn!D9 -> 0 | C11: =+Zn!E9 -> 0 | E11: =+Zn!H9 -> P | F11: =IF(D11=0,AVERAGE(B11,C11),IF(OR(AND(B11<C11,B11>D11),AND(B11>C11,B11<D11)),B11,IF(OR(AND(C11<B11,C11>D11),AND(C11>B11,C11<D11)),C11,D11))) -> 0 | G11: =IF(D11=0,0,IF(D11>B11,(D11-B11),(B11-D11))) -> 0 | H11: =IF(D11=0,0,IF(C11>D11,(C11-D11),(D11-C11))) -> 0 | I11: =IF(D11=0,"",IF(H11=G11,"50%",IF(H11>G11,"CIEN","MMP"))) | J11: =+Zn!J9 -> 0 | K11: =+Zn!K9 -> 0 | M11: =+Zn!N9 -> P | N11: =IF(L11=0,AVERAGE(J11,K11),IF(OR(AND(J11<K11,J11>L11),AND(J11>K11,J11<L11)),J11,IF(OR(AND(K11<J11,K11>L11),AND(K11>J11,K11<L11)),K11,L11))) -> 0 | O11: =IF(L11=0,0,IF(L11>J11,(L11-J11),(J11-L11))) -> 0 | P11: =IF(L11=0,0,IF(K11>L11,(K11-L11),(L11-K11))) -> 0 | Q11: =IF(L11=0,"",IF(P11=O11,"50%",IF(P11>O11,"CIEN","MMP"))) | R11: =+Zn!P9 -> 0 | S11: =+Zn!Q9 -> 0 | U11: =+Zn!T9 -> P | V11: =IF(T11=0,AVERAGE(R11,S11),IF(OR(AND(R11<S11,R11>T11),AND(R11>S11,R11<T11)),R11,IF(OR(AND(S11<R11,S11>T11),AND(S11>R11,S11<T11)),S11,T11))) -> 0 | W11: =IF(T11=0,0,IF(T11>R11,(T11-R11),(R11-T11))) -> 0 | X11: =IF(T11=0,0,IF(S11>T11,(S11-T11),(T11-S11))) -> 0 | Y11: =IF(T11=0,"",IF(X11=W11,"50%",IF(X11>W11,"CIEN","MMP"))) | Z11: =+Zn!AN9 -> 0 | AA11: =+Zn!AO9 -> 0 | AC11: =+Zn!AR9 -> P | AD11: =IF(AB11=0,AVERAGE(Z11,AA11),IF(OR(AND(Z11<AA11,Z11>AB11),AND(Z11>AA11,Z11<AB11)),Z11,IF(OR(AND(AA11<Z11,AA11>AB11),AND(AA11>Z11,AA11<AB11)),AA11,AB11))) -> 0 | AE11: =IF(Z11>AB11,(Z11-AB11),(AB11-Z11)) -> 0 | AF11: =IF(AA11>AB11,(AA11-AB11),(AB11-AA11)) -> 0 | AG11: =IF(AB11=0,"",IF(AF11=AE11,"50%",IF(AF11>AE11,"CIEN","MMP"))) | AH11: =+Zn!V9 -> 0 | AI11: =+Zn!W9 -> 0 | AK11: =+Zn!Z9 -> P | AL11: =IF(AJ11=0,AVERAGE(AH11,AI11),IF(OR(AND(AH11<AI11,AH11>AJ11),AND(AH11>AI11,AH11<AJ11)),AH11,IF(OR(AND(AI11<AH11,AI11>AJ11),AND(AI11>AH11,AI11<AJ11)),AI11,AJ11))) -> 0 | AM11: =IF(AJ11>AH11,(AJ11-AH11),(AH11-AJ11)) -> 0 | AN11: =IF(AI11>AJ11,(AI11-AJ11),(AJ11-AI11)) -> 0 | AO11: =IF(AJ11=0,"",IF(AN11=AM11,"50%",IF(AN11>AM11,"CIEN","MMP"))) | AP11: =+Zn!AH9 -> 0 | AQ11: =+Zn!AI9 -> 0 | AS11: =+Zn!AL9 -> P | AT11: =IF(AR11=0,AVERAGE(AP11,AQ11),IF(OR(AND(AP11<AQ11,AP11>AR11),AND(AP11>AQ11,AP11<AR11)),AP11,IF(OR(AND(AQ11<AP11,AQ11>AR11),AND(AQ11>AP11,AQ11<AR11)),AQ11,AR11))) -> 0 | AU11: =IF(AR11>AP11,(AR11-AP11),(AP11-AR11)) -> 0 | AV11: =IF(AQ11>AR11,(AQ11-AR11),(AR11-AQ11)) -> 0 | AW11: =IF(AR11=0,"",IF(AV11=AU11,"50%",IF(AV11>AU11,"CIEN","MMP"))) | AX11: =+Zn!AT9 -> 0 | AY11: =+Zn!AU9 -> 0 | BA11: =+Zn!AX9 -> P | BB11: =IF(AZ11=0,AVERAGE(AX11,AY11),IF(OR(AND(AX11<AY11,AX11>AZ11),AND(AX11>AY11,AX11<AZ11)),AX11,IF(OR(AND(AY11<AX11,AY11>AZ11),AND(AY11>AX11,AY11<AZ11)),AY11,AZ11))) -> 0 | BC11: =IF(AZ11>AX11,(AZ11-AX11),(AX11-AZ11)) -> 0 | BD11: =IF(AY11>AZ11,(AY11-AZ11),(AZ11-AY11)) -> 0 | BE11: =IF(AZ11=0,"",IF(BD11=BC11,"50%",IF(BD11>BC11,"CIEN","MMP"))) | BF11: =+Zn!AB9 -> 0 | BG11: =+Zn!AC9 -> 0 | BI11: =+Zn!AF9 -> P | BJ11: =IF(BH11=0,AVERAGE(BF11,BG11),IF(OR(AND(BF11<BG11,BF11>BH11),AND(BF11>BG11,BF11<BH11)),BF11,IF(OR(AND(BG11<BF11,BG11>BH11),AND(BG11>BF11,BG11<BH11)),BG11,BH11))) -> 0 | BK11: =IF(BH11>BF11,(BH11-BF11),(BF11-BH11)) -> 0 | BL11: =IF(BG11>BH11,(BG11-BH11),(BH11-BG11)) -> 0 | BM11: =IF(BH11=0,"",IF(BL11=BK11,"50%",IF(BL11>BK11,"CIEN","MMP")))
